Workbook

Sheet Carnes
A1: Carnes | F1: 1 | I1: 2 | L1: 3 | O1: 4 | R1: 5 | U1: 6 | X1: 7 | AA1: 8 | AD1: 9 | AG1: 10 | AJ1: 11 | AM1: 12 | AP1: 13 | AS1: 14 | AV1: 15 | AY1: 16 | BB1: 17 | BE1: 18 | BH1: 19 | BK1: 20 | BN1: 21 | BQ1: 22 | BT1: 23 | BW1: 24 | BZ1: 25 | CC1: 26 | CF1: 27 | CI1: 28 | CL1: 29 | CO1: 30 | CR1: 31 | CU1: Total mes
A2: Producto | B2: Medidas | C2: Cantidad | D2: Valor | E2: Total | F2: Cantid | G2: Costo unit | H2: Vr. compra | I2: Cantid | J2: Costo unit | K2: Vr. compra | L2: Cantid | M2: Costo unit | N2: Vr. compra | O2: Cantid | P2: Costo unit | Q2: Vr. compra | R2: Cantid | S2: Costo | T2: Vr. compra | U2: Cantid | V2: Costo unit | W2: Vr. compra | X2: Cantid | Y2: Costo unit | Z2: Vr. compra | AA2: Cantid | AB2: Costo unit | AC2: Vr. compra | AD2: Cantid | AE2: Costo unit | AF2: Vr. compra | AG2: Cantid | AH2: Costo unit | AI2: Vr. compra | AJ2: Cantid | AK2: Costo unit | AL2: Vr. compra | AM2: Cantid | AN2: Costo unit | AO2: Vr. compra | AP2: Cantid | AQ2: Costo | AR2: Vr. compra | AS2: Cantid | AT2: Costo unit | AU2: Vr. compra | AV2: Cantid | AW2: Costo unit | AX2: Vr. compra | AY2: Cantid | AZ2: Costo unit | BA2: Vr. compra | BB2: Cantid | BC2: Costo unit | BD2: Vr. compra | BE2: Cantid | BF2: Costo unit | BG2: Vr. compra | BH2: Cantid | BI2: Costo unit | BJ2: Vr. compra | BK2: Cantid | BL2: Costo unit | BM2: Vr. compra | BN2: Cantid | BO2: Costo | BP2: Vr. compra | BQ2: Cantid | BR2: Costo unit | BS2: Vr. compra | BT2: Cantid | BU2: Costo unit | BV2: Vr. compra | BW2: Cantid | BX2: Costo unit | BY2: Vr. compra | BZ2: Cantid | CA2: Costo unit | CB2: Vr. compra | CC2: Cantid | CD2: Costo unit | CE2: Vr. compra | CF2: Cantid | CG2: Costo unit | CH2: Vr. compra | CI2: Cantid | CJ2: Costo unit | CK2: Vr. compra | CL2: Cantid | CM2: Costo unit | CN2: Vr. compra | CO2: Cantid | CP2: Costo unit | CQ2: Vr. compra | CR2: Cantid | CS2: Costo unit | CT2: Vr. compra | CU2: Cantid | CV2: Costo unit | CW2: Vr. compra
A3: Alas de pollo | B3: Kg | E3: 0 | H3: =IFERROR(F3*G3, 0) | K3: =IFERROR(I3*J3, 0) | N3: =IFERROR(L3*M3, 0) | Q3: =IFERROR(O3*P3, 0) | T3: =IFERROR(R3*S3, 0) | W3: =IFERROR(U3*V3, 0) | X3: 3.176 | Y3: 14500 | Z3: 46052 | AA3: 3.145 | AB3: 14500 | AC3: 45603 | AF3: =IFERROR(AD3*AE3, 0) | AI3: =IFERROR(AG3*AH3, 0) | AL3: =IFERROR(AJ3*AK3, 0) | AO3: =IFERROR(AM3*AN3, 0) | AR3: =IFERROR(AP3*AQ3, 0) | AU3: =IFERROR(AS3*AT3, 0) | AX3: =IFERROR(AV3*AW3, 0) | BA3: =IFERROR(AY3*AZ3, 0) | BD3: =IFERROR(BB3*BC3, 0) | BG3: =IFERROR(BE3*BF3, 0) | BJ3: =IFERROR(BH3*BI3, 0) | BM3: =IFERROR(BK3*BL3, 0) | BP3: =IFERROR(BN3*BO3, 0) | BS3: =IFERROR(BQ3*BR3, 0) | BV3: =IFERROR(BT3*BU3, 0) | BW3: 10 | BX3: 5000 | BY3: 50000 | CB3: =IFERROR(BZ3*CA3, 0) | CE3: =IFERROR(CC3*CD3, 0) | CH3: =IFERROR(CF3*CG3, 0) | CK3: =IFERROR(CI3*CJ3, 0) | CN3: =IFERROR(CL3*CM3, 0) | CQ3: =IFERROR(CO3*CP3, 0) | CT3: =IFERROR(CR3*CS3, 0) | CU3: =IFERROR(SUM(F3,I3,L3,O3,R3,U3,X3,AA3,AD3,AG3,AJ3,AM3,AP3,AS3,AV3,AY3,BB3,BE3,BH3,BK3,BN3,BQ3,BT3,BW3,BZ3,CC3,CF3,CI3,CL3,CO3,CR3), 0) | CV3: =IFERROR(AVERAGE(G3,J3,M3,P3,S3,V3,Y3,AB3,AE3,AH3,AK3,AN3,AQ3,AT3,AW3,AZ3,BC3,BF3,BI3,BL3,BO3,BR3,BU3,BX3,CA3,CD3,CG3,CJ3,CM3,CP3,CS3), 0) | CW3: =CU3*CV3
A4: Bagre de mar | B4: Kg | E4: 0 | H4: =IFERROR(F4*G4, 0) | I4: 20 | J4: 16500 | K4: 330000 | N4: =IFERROR(L4*M4, 0) | Q4: =IFERROR(O4*P4, 0) | T4: =IFERROR(R4*S4, 0) | W4: =IFERROR(U4*V4, 0) | Z4: =IFERROR(X4*Y4, 0) | AA4: 21 | AB4: 16500 | AC4: 759000 | AF4: =IFERROR(AD4*AE4, 0) | AI4: =IFERROR(AG4*AH4, 0) | AL4: =IFERROR(AJ4*AK4, 0) | AO4: =IFERROR(AM4*AN4, 0) | AR4: =IFERROR(AP4*AQ4, 0) | AU4: =IFERROR(AS4*AT4, 0) | AV4: 26 | AW4: 16500 | AX4: 429000 | BA4: =IFERROR(AY4*AZ4, 0) | BD4: =IFERROR(BB4*BC4, 0) | BG4: =IFERROR(BE4*BF4, 0) | BJ4: =IFERROR(BH4*BI4, 0) | BM4: =IFERROR(BK4*BL4, 0) | BP4: =IFERROR(BN4*BO4, 0) | BS4: =IFERROR(BQ4*BR4, 0) | BT4: 22.12 | BU4: 17000 | BV4: 376040 | BY4: =IFERROR(BW4*BX4, 0) | CB4: =IFERROR(BZ4*CA4, 0) | CE4: =IFERROR(CC4*CD4, 0) | CH4: =IFERROR(CF4*CG4, 0) | CK4: =IFERROR(CI4*CJ4, 0) | CN4: =IFERROR(CL4*CM4, 0) | CQ4: =IFERROR(CO4*CP4, 0) | CT4: =IFERROR(CR4*CS4, 0) | CU4: =IFERROR(SUM(F4,I4,L4,O4,R4,U4,X4,AA4,AD4,AG4,AJ4,AM4,AP4,AS4,AV4,AY4,BB4,BE4,BH4,BK4,BN4,BQ4,BT4,BW4,BZ4,CC4,CF4,CI4,CL4,CO4,CR4), 0) | CV4: =IFERROR(AVERAGE(G4,J4,M4,P4,S4,V4,Y4,AB4,AE4,AH4,AK4,AN4,AQ4,AT4,AW4,AZ4,BC4,BF4,BI4,BL4,BO4,BR4,BU4,BX4,CA4,CD4,CG4,CJ4,CM4,CP4,CS4), 0) | CW4: =CU4*CV4
A5: Barcino de res | B5: Kg | E5: 0 | H5: =IFERROR(F5*G5, 0) | K5: =IFERROR(I5*J5, 0) | N5: =IFERROR(L5*M5, 0) | Q5: =IFERROR(O5*P5, 0) | T5: =IFERROR(R5*S5, 0) | W5: =IFERROR(U5*V5, 0) | X5: 19.55 | Y5: 26900 | Z5: 525895 | AC5: =IFERROR(AA5*AB5, 0) | AF5: =IFERROR(AD5*AE5, 0) | AG5: 27.1 | AH5: 26900 | AI5: 728990 | AL5: =IFERROR(AJ5*AK5, 0) | AO5: =IFERROR(AM5*AN5, 0) | AR5: =IFERROR(AP5*AQ5, 0) | AU5: =IFERROR(AS5*AT5, 0) | AV5: 23.2 | AW5: 26900 | AX5: 624080 | BA5: =IFERROR(AY5*AZ5, 0) | BB5: 24.2 | BC5: 26900 | BD5: 650980 | BG5: =IFERROR(BE5*BF5, 0) | BJ5: =IFERROR(BH5*BI5, 0) | BM5: =IFERROR(BK5*BL5, 0) | BP5: =IFERROR(BN5*BO5, 0) | BS5: =IFERROR(BQ5*BR5, 0) | BT5: 21.5 | BU5: 26900 | BV5: 578350 | BY5: =IFERROR(BW5*BX5, 0) | CB5: =IFERROR(BZ5*CA5, 0) | CE5: =IFERROR(CC5*CD5, 0) | CH5: =IFERROR(CF5*CG5, 0) | CK5: =IFERROR(CI5*CJ5, 0) | CN5: =IFERROR(CL5*CM5, 0) | CQ5: =IFERROR(CO5*CP5, 0) | CT5: =IFERROR(CR5*CS5, 0) | CU5: =IFERROR(SUM(F5,I5,L5,O5,R5,U5,X5,AA5,AD5,AG5,AJ5,AM5,AP5,AS5,AV5,AY5,BB5,BE5,BH5,BK5,BN5,BQ5,BT5,BW5,BZ5,CC5,CF5,CI5,CL5,CO5,CR5), 0) | CV5: =IFERROR(AVERAGE(G5,J5,M5,P5,S5,V5,Y5,AB5,AE5,AH5,AK5,AN5,AQ5,AT5,AW5,AZ5,BC5,BF5,BI5,BL5,BO5,BR5,BU5,BX5,CA5,CD5,CG5,CJ5,CM5,CP5,CS5), 0) | CW5: =CU5*CV5
A6: Bola negra | B6: Kg | E6: 0 | H6: =IFERROR(F6*G6, 0) | K6: =IFERROR(I6*J6, 0) | N6: =IFERROR(L6*M6, 0) | Q6: =IFERROR(O6*P6, 0) | T6: =IFERROR(R6*S6, 0) | W6: =IFERROR(U6*V6, 0) | Z6: =IFERROR(X6*Y6, 0) | AC6: =IFERROR(AA6*AB6, 0) | AF6: =IFERROR(AD6*AE6, 0) | AI6: =IFERROR(AG6*AH6, 0) | AJ6: 8.07 | AK6: 34000 | AL6: 274380 | AO6: =IFERROR(AM6*AN6, 0) | AR6: =IFERROR(AP6*AQ6, 0) | AU6: =IFERROR(AS6*AT6, 0) | AX6: =IFERROR(AV6*AW6, 0) | BA6: =IFERROR(AY6*AZ6, 0) | BD6: =IFERROR(BB6*BC6, 0) | BG6: =IFERROR(BE6*BF6, 0) | BJ6: =IFERROR(BH6*BI6, 0) | BM6: =IFERROR(BK6*BL6, 0) | BP6: =IFERROR(BN6*BO6, 0) | BS6: =IFERROR(BQ6*BR6, 0) | BV6: =IFERROR(BT6*BU6, 0) | BY6: =IFERROR(BW6*BX6, 0) | CB6: =IFERROR(BZ6*CA6, 0) | CE6: =IFERROR(CC6*CD6, 0) | CH6: =IFERROR(CF6*CG6, 0) | CK6: =IFERROR(CI6*CJ6, 0) | CN6: =IFERROR(CL6*CM6, 0) | CQ6: =IFERROR(CO6*CP6, 0) | CT6: =IFERROR(CR6*CS6, 0) | CU6: =IFERROR(SUM(F6,I6,L6,O6,R6,U6,X6,AA6,AD6,AG6,AJ6,AM6,AP6,AS6,AV6,AY6,BB6,BE6,BH6,BK6,BN6,BQ6,BT6,BW6,BZ6,CC6,CF6,CI6,CL6,CO6,CR6), 0) | CV6: =IFERROR(AVERAGE(G6,J6,M6,P6,S6,V6,Y6,AB6,AE6,AH6,AK6,AN6,AQ6,AT6,AW6,AZ6,BC6,BF6,BI6,BL6,BO6,BR6,BU6,BX6,CA6,CD6,CG6,CJ6,CM6,CP6,CS6), 0) | CW6: =CU6*CV6
A7: Bondiola importada | B7: Kg | E7: 0 | H7: =IFERROR(F7*G7, 0) | K7: =IFERROR(I7*J7, 0) | N7: =IFERROR(L7*M7, 0) | Q7: =IFERROR(O7*P7, 0) | T7: =IFERROR(R7*S7, 0) | W7: =IFERROR(U7*V7, 0) | Z7: =IFERROR(X7*Y7, 0) | AC7: =IFERROR(AA7*AB7, 0) | AF7: =IFERROR(AD7*AE7, 0) | AI7: =IFERROR(AG7*AH7, 0) | AL7: =IFERROR(AJ7*AK7, 0) | AO7: =IFERROR(AM7*AN7, 0) | AR7: =IFERROR(AP7*AQ7, 0) | AU7: =IFERROR(AS7*AT7, 0) | AX7: =IFERROR(AV7*AW7, 0) | BA7: =IFERROR(AY7*AZ7, 0) | BD7: =IFERROR(BB7*BC7, 0) | BG7: =IFERROR(BE7*BF7, 0) | BJ7: =IFERROR(BH7*BI7, 0) | BM7: =IFERROR(BK7*BL7, 0) | BP7: =IFERROR(BN7*BO7, 0) | BS7: =IFERROR(BQ7*BR7, 0) | BV7: =IFERROR(BT7*BU7, 0) | BY7: =IFERROR(BW7*BX7, 0) | CB7: =IFERROR(BZ7*CA7, 0) | CE7: =IFERROR(CC7*CD7, 0) | CH7: =IFERROR(CF7*CG7, 0) | CK7: =IFERROR(CI7*CJ7, 0) | CN7: =IFERROR(CL7*CM7, 0) | CQ7: =IFERROR(CO7*CP7, 0) | CT7: =IFERROR(CR7*CS7, 0) | CU7: =IFERROR(SUM(F7,I7,L7,O7,R7,U7,X7,AA7,AD7,AG7,AJ7,AM7,AP7,AS7,AV7,AY7,BB7,BE7,BH7,BK7,BN7,BQ7,BT7,BW7,BZ7,CC7,CF7,CI7,CL7,CO7,CR7), 0) | CV7: =IFERROR(AVERAGE(G7,J7,M7,P7,S7,V7,Y7,AB7,AE7,AH7,AK7,AN7,AQ7,AT7,AW7,AZ7,BC7,BF7,BI7,BL7,BO7,BR7,BU7,BX7,CA7,CD7,CG7,CJ7,CM7,CP7,CS7), 0) | CW7: =CU7*CV7
A8: Cabeza de lomo | B8: Kg | E8: 0 | H8: =IFERROR(F8*G8, 0) | K8: =IFERROR(I8*J8, 0) | N8: =IFERROR(L8*M8, 0) | Q8: =IFERROR(O8*P8, 0) | T8: =IFERROR(R8*S8, 0) | W8: =IFERROR(U8*V8, 0) | Z8: =IFERROR(X8*Y8, 0) | AC8: =IFERROR(AA8*AB8, 0) | AF8: =IFERROR(AD8*AE8, 0) | AI8: =IFERROR(AG8*AH8, 0) | AL8: =IFERROR(AJ8*AK8, 0) | AO8: =IFERROR(AM8*AN8, 0) | AR8: =IFERROR(AP8*AQ8, 0) | AU8: =IFERROR(AS8*AT8, 0) | AX8: =IFERROR(AV8*AW8, 0) | BA8: =IFERROR(AY8*AZ8, 0) | BD8: =IFERROR(BB8*BC8, 0) | BG8: =IFERROR(BE8*BF8, 0) | BJ8: =IFERROR(BH8*BI8, 0) | BM8: =IFERROR(BK8*BL8, 0) | BP8: =IFERROR(BN8*BO8, 0) | BS8: =IFERROR(BQ8*BR8, 0) | BV8: =IFERROR(BT8*BU8, 0) | BY8: =IFERROR(BW8*BX8, 0) | CB8: =IFERROR(BZ8*CA8, 0) | CE8: =IFERROR(CC8*CD8, 0) | CH8: =IFERROR(CF8*CG8, 0) | CK8: =IFERROR(CI8*CJ8, 0) | CN8: =IFERROR(CL8*CM8, 0) | CQ8: =IFERROR(CO8*CP8, 0) | CT8: =IFERROR(CR8*CS8, 0) | CU8: =IFERROR(SUM(F8,I8,L8,O8,R8,U8,X8,AA8,AD8,AG8,AJ8,AM8,AP8,AS8,AV8,AY8,BB8,BE8,BH8,BK8,BN8,BQ8,BT8,BW8,BZ8,CC8,CF8,CI8,CL8,CO8,CR8), 0) | CV8: =IFERROR(AVERAGE(G8,J8,M8,P8,S8,V8,Y8,AB8,AE8,AH8,AK8,AN8,AQ8,AT8,AW8,AZ8,BC8,BF8,BI8,BL8,BO8,BR8,BU8,BX8,CA8,CD8,CG8,CJ8,CM8,CP8,CS8), 0) | CW8: =CU8*CV8
A9: Caderita | B9: Kg | E9: 0 | H9: =IFERROR(F9*G9, 0) | K9: =IFERROR(I9*J9, 0) | N9: =IFERROR(L9*M9, 0) | Q9: =IFERROR(O9*P9, 0) | T9: =IFERROR(R9*S9, 0) | W9: =IFERROR(U9*V9, 0) | Z9: =IFERROR(X9*Y9, 0) | AC9: =IFERROR(AA9*AB9, 0) | AD9: 6.04 | AE9: 34000 | AF9: 205360 | AI9: =IFERROR(AG9*AH9, 0) | AL9: =IFERROR(AJ9*AK9, 0) | AO9: =IFERROR(AM9*AN9, 0) | AR9: =IFERROR(AP9*AQ9, 0) | AU9: =IFERROR(AS9*AT9, 0) | AV9: 10.1 | AW9: 33000 | AX9: 333300 | BA9: =IFERROR(AY9*AZ9, 0) | BD9: =IFERROR(BB9*BC9, 0) | BG9: =IFERROR(BE9*BF9, 0) | BJ9: =IFERROR(BH9*BI9, 0) | BM9: =IFERROR(BK9*BL9, 0) | BP9: =IFERROR(BN9*BO9, 0) | BS9: =IFERROR(BQ9*BR9, 0) | BV9: =IFERROR(BT9*BU9, 0) | BY9: =IFERROR(BW9*BX9, 0) | CB9: =IFERROR(BZ9*CA9, 0) | CE9: =IFERROR(CC9*CD9, 0) | CH9: =IFERROR(CF9*CG9, 0) | CK9: =IFERROR(CI9*CJ9, 0) | CN9: =IFERROR(CL9*CM9, 0) | CQ9: =IFERROR(CO9*CP9, 0) | CT9: =IFERROR(CR9*CS9, 0) | CU9: =IFERROR(SUM(F9,I9,L9,O9,R9,U9,X9,AA9,AD9,AG9,AJ9,AM9,AP9,AS9,AV9,AY9,BB9,BE9,BH9,BK9,BN9,BQ9,BT9,BW9,BZ9,CC9,CF9,CI9,CL9,CO9,CR9), 0) | CV9: =IFERROR(AVERAGE(G9,J9,M9,P9,S9,V9,Y9,AB9,AE9,AH9,AK9,AN9,AQ9,AT9,AW9,AZ9,BC9,BF9,BI9,BL9,BO9,BR9,BU9,BX9,CA9,CD9,CG9,CJ9,CM9,CP9,CS9), 0) | CW9: =CU9*CV9
A10: Callo | B10: Kg | E10: 0 | H10: =IFERROR(F10*G10, 0) | K10: =IFERROR(I10*J10, 0) | N10: =IFERROR(L10*M10, 0) | Q10: =IFERROR(O10*P10, 0) | R10: 7.65 | S10: 18000 | T10: 137700 | W10: =IFERROR(U10*V10, 0) | Z10: =IFERROR(X10*Y10, 0) | AC10: =IFERROR(AA10*AB10, 0) | AF10: =IFERROR(AD10*AE10, 0) | AI10: =IFERROR(AG10*AH10, 0) | AL10: =IFERROR(AJ10*AK10, 0) | AO10: =IFERROR(AM10*AN10, 0) | AR10: =IFERROR(AP10*AQ10, 0) | AU10: =IFERROR(AS10*AT10, 0) | AX10: =IFERROR(AV10*AW10, 0) | BA10: =IFERROR(AY10*AZ10, 0) | BD10: =IFERROR(BB10*BC10, 0) | BG10: =IFERROR(BE10*BF10, 0) | BJ10: =IFERROR(BH10*BI10, 0) | BM10: =IFERROR(BK10*BL10, 0) | BP10: =IFERROR(BN10*BO10, 0) | BS10: =IFERROR(BQ10*BR10, 0) | BV10: =IFERROR(BT10*BU10, 0) | BY10: =IFERROR(BW10*BX10, 0) | CB10: =IFERROR(BZ10*CA10, 0) | CE10: =IFERROR(CC10*CD10, 0) | CH10: =IFERROR(CF10*CG10, 0) | CK10: =IFERROR(CI10*CJ10, 0) | CN10: =IFERROR(CL10*CM10, 0) | CQ10: =IFERROR(CO10*CP10, 0) | CT10: =IFERROR(CR10*CS10, 0) | CU10: =IFERROR(SUM(F10,I10,L10,O10,R10,U10,X10,AA10,AD10,AG10,AJ10,AM10,AP10,AS10,AV10,AY10,BB10,BE10,BH10,BK10,BN10,BQ10,BT10,BW10,BZ10,CC10,CF10,CI10,CL10,CO10,CR10), 0) | CV10: =IFERROR(AVERAGE(G10,J10,M10,P10,S10,V10,Y10,AB10,AE10,AH10,AK10,AN10,AQ10,AT10,AW10,AZ10,BC10,BF10,BI10,BL10,BO10,BR10,BU10,BX10,CA10,CD10,CG10,CJ10,CM10,CP10,CS10), 0) | CW10: =CU10*CV10
A11: Callo distribuidora myc sas | B11: Kg | E11: 0 | H11: =IFERROR(F11*G11, 0) | K11: =IFERROR(I11*J11, 0) | N11: =IFERROR(L11*M11, 0) | Q11: =IFERROR(O11*P11, 0) | T11: =IFERROR(R11*S11, 0) | W11: =IFERROR(U11*V11, 0) | Z11: =IFERROR(X11*Y11, 0) | AC11: =IFERROR(AA11*AB11, 0) | AF11: =IFERROR(AD11*AE11, 0) | AI11: =IFERROR(AG11*AH11, 0) | AL11: =IFERROR(AJ11*AK11, 0) | AO11: =IFERROR(AM11*AN11, 0) | AR11: =IFERROR(AP11*AQ11, 0) | AU11: =IFERROR(AS11*AT11, 0) | AX11: =IFERROR(AV11*AW11, 0) | BA11: =IFERROR(AY11*AZ11, 0) | BD11: =IFERROR(BB11*BC11, 0) | BG11: =IFERROR(BE11*BF11, 0) | BJ11: =IFERROR(BH11*BI11, 0) | BM11: =IFERROR(BK11*BL11, 0) | BP11: =IFERROR(BN11*BO11, 0) | BS11: =IFERROR(BQ11*BR11, 0) | BV11: =IFERROR(BT11*BU11, 0) | BY11: =IFERROR(BW11*BX11, 0) | CB11: =IFERROR(BZ11*CA11, 0) | CE11: =IFERROR(CC11*CD11, 0) | CH11: =IFERROR(CF11*CG11, 0) | CK11: =IFERROR(CI11*CJ11, 0) | CN11: =IFERROR(CL11*CM11, 0) | CQ11: =IFERROR(CO11*CP11, 0) | CT11: =IFERROR(CR11*CS11, 0) | CU11: =IFERROR(SUM(F11,I11,L11,O11,R11,U11,X11,AA11,AD11,AG11,AJ11,AM11,AP11,AS11,AV11,AY11,BB11,BE11,BH11,BK11,BN11,BQ11,BT11,BW11,BZ11,CC11,CF11,CI11,CL11,CO11,CR11), 0) | CV11: =IFERROR(AVERAGE(G11,J11,M11,P11,S11,V11,Y11,AB11,AE11,AH11,AK11,AN11,AQ11,AT11,AW11,AZ11,BC11,BF11,BI11,BL11,BO11,BR11,BU11,BX11,CA11,CD11,CG11,CJ11,CM11,CP11,CS11), 0) | CW11: =CU11*CV11
A12: Camaron precocido | B12: Kg | E12: 0 | H12: =IFERROR(F12*G12, 0) | I12: 30.7 | J12: 22900 | K12: 703030 | N12: =IFERROR(L12*M12, 0) | Q12: =IFERROR(O12*P12, 0) | T12: =IFERROR(R12*S12, 0) | W12: =IFERROR(U12*V12, 0) | Z12: =IFERROR(X12*Y12, 0) | AC12: =IFERROR(AA12*AB12, 0) | AF12: =IFERROR(AD12*AE12, 0) | AG12: 20.2 | AH12: 22900 | AI12: 462580 | AL12: =IFERROR(AJ12*AK12, 0) | AO12: =IFERROR(AM12*AN12, 0) | AR12: =IFERROR(AP12*AQ12, 0) | AU12: =IFERROR(AS12*AT12, 0) | AX12: =IFERROR(AV12*AW12, 0) | BA12: =IFERROR(AY12*AZ12, 0) | BB12: 20.2 | BC12: 22900 | BD12: 462580 | BG12: =IFERROR(BE12*BF12, 0) | BJ12: =IFERROR(BH12*BI12, 0) | BM12: =IFERROR(BK12*BL12, 0) | BP12: =IFERROR(BN12*BO12, 0) | BS12: =IFERROR(BQ12*BR12, 0) | BV12: =IFERROR(BT12*BU12, 0) | BY12: =IFERROR(BW12*BX12, 0) | CB12: =IFERROR(BZ12*CA12, 0) | CE12: =IFERROR(CC12*CD12, 0) | CH12: =IFERROR(CF12*CG12, 0) | CK12: =IFERROR(CI12*CJ12, 0) | CN12: =IFERROR(CL12*CM12, 0) | CQ12: =IFERROR(CO12*CP12, 0) | CT12: =IFERROR(CR12*CS12, 0) | CU12: =IFERROR(SUM(F12,I12,L12,O12,R12,U12,X12,AA12,AD12,AG12,AJ12,AM12,AP12,AS12,AV12,AY12,BB12,BE12,BH12,BK12,BN12,BQ12,BT12,BW12,BZ12,CC12,CF12,CI12,CL12,CO12,CR12), 0) | CV12: =IFERROR(AVERAGE(G12,J12,M12,P12,S12,V12,Y12,AB12,AE12,AH12,AK12,AN12,AQ12,AT12,AW12,AZ12,BC12,BF12,BI12,BL12,BO12,BR12,BU12,BX12,CA12,CD12,CG12,CJ12,CM12,CP12,CS12), 0) | CW12: =CU12*CV12
A13: Carne molida | B13: Kg | E13: 0 | H13: =IFERROR(F13*G13, 0) | K13: =IFERROR(I13*J13, 0) | N13: =IFERROR(L13*M13, 0) | Q13: =IFERROR(O13*P13, 0) | T13: =IFERROR(R13*S13, 0) | W13: =IFERROR(U13*V13, 0) | Z13: =IFERROR(X13*Y13, 0) | AC13: =IFERROR(AA13*AB13, 0) | AF13: =IFERROR(AD13*AE13, 0) | AI13: =IFERROR(AG13*AH13, 0) | AL13: =IFERROR(AJ13*AK13, 0) | AO13: =IFERROR(AM13*AN13, 0) | AR13: =IFERROR(AP13*AQ13, 0) | AU13: =IFERROR(AS13*AT13, 0) | AX13: =IFERROR(AV13*AW13, 0) | BA13: =IFERROR(AY13*AZ13, 0) | BD13: =IFERROR(BB13*BC13, 0) | BG13: =IFERROR(BE13*BF13, 0) | BJ13: =IFERROR(BH13*BI13, 0) | BM13: =IFERROR(BK13*BL13, 0) | BP13: =IFERROR(BN13*BO13, 0) | BS13: =IFERROR(BQ13*BR13, 0) | BV13: =IFERROR(BT13*BU13, 0) | BY13: =IFERROR(BW13*BX13, 0) | CB13: =IFERROR(BZ13*CA13, 0) | CE13: =IFERROR(CC13*CD13, 0) | CH13: =IFERROR(CF13*CG13, 0) | CK13: =IFERROR(CI13*CJ13, 0) | CN13: =IFERROR(CL13*CM13, 0) | CQ13: =IFERROR(CO13*CP13, 0) | CT13: =IFERROR(CR13*CS13, 0) | CU13: =IFERROR(SUM(F13,I13,L13,O13,R13,U13,X13,AA13,AD13,AG13,AJ13,AM13,AP13,AS13,AV13,AY13,BB13,BE13,BH13,BK13,BN13,BQ13,BT13,BW13,BZ13,CC13,CF13,CI13,CL13,CO13,CR13), 0) | CV13: =IFERROR(AVERAGE(G13,J13,M13,P13,S13,V13,Y13,AB13,AE13,AH13,AK13,AN13,AQ13,AT13,AW13,AZ13,BC13,BF13,BI13,BL13,BO13,BR13,BU13,BX13,CA13,CD13,CG13,CJ13,CM13,CP13,CS13), 0) | CW13: =CU13*CV13
A14: Pecho | B14: Kg | E14: 0 | H14: =IFERROR(F14*G14, 0) | K14: =IFERROR(I14*J14, 0) | N14: =IFERROR(L14*M14, 0) | Q14: =IFERROR(O14*P14, 0) | T14: =IFERROR(R14*S14, 0) | W14: =IFERROR(U14*V14, 0) | Z14: =IFERROR(X14*Y14, 0) | AC14: =IFERROR(AA14*AB14, 0) | AF14: =IFERROR(AD14*AE14, 0) | AI14: =IFERROR(AG14*AH14, 0) | AL14: =IFERROR(AJ14*AK14, 0) | AO14: =IFERROR(AM14*AN14, 0) | AR14: =IFERROR(AP14*AQ14, 0) | AU14: =IFERROR(AS14*AT14, 0) | AX14: =IFERROR(AV14*AW14, 0) | BA14: =IFERROR(AY14*AZ14, 0) | BD14: =IFERROR(BB14*BC14, 0) | BG14: =IFERROR(BE14*BF14, 0) | BJ14: =IFERROR(BH14*BI14, 0) | BM14: =IFERROR(BK14*BL14, 0) | BP14: =IFERROR(BN14*BO14, 0) | BS14: =IFERROR(BQ14*BR14, 0) | BV14: =IFERROR(BT14*BU14, 0) | BY14: =IFERROR(BW14*BX14, 0) | CB14: =IFERROR(BZ14*CA14, 0) | CE14: =IFERROR(CC14*CD14, 0) | CH14: =IFERROR(CF14*CG14, 0) | CK14: =IFERROR(CI14*CJ14, 0) | CN14: =IFERROR(CL14*CM14, 0) | CQ14: =IFERROR(CO14*CP14, 0) | CT14: =IFERROR(CR14*CS14, 0) | CU14: =IFERROR(SUM(F14,I14,L14,O14,R14,U14,X14,AA14,AD14,AG14,AJ14,AM14,AP14,AS14,AV14,AY14,BB14,BE14,BH14,BK14,BN14,BQ14,BT14,BW14,BZ14,CC14,CF14,CI14,CL14,CO14,CR14), 0) | CV14: =IFERROR(AVERAGE(G14,J14,M14,P14,S14,V14,Y14,AB14,AE14,AH14,AK14,AN14,AQ14,AT14,AW14,AZ14,BC14,BF14,BI14,BL14,BO14,BR14,BU14,BX14,CA14,CD14,CG14,CJ14,CM14,CP14,CS14), 0) | CW14: =CU14*CV14
A15: Muchacho res | B15: Kg | E15: 0 | H15: =IFERROR(F15*G15, 0) | K15: =IFERROR(I15*J15, 0) | N15: =IFERROR(L15*M15, 0) | Q15: =IFERROR(O15*P15, 0) | T15: =IFERROR(R15*S15, 0) | W15: =IFERROR(U15*V15, 0) | Z15: =IFERROR(X15*Y15, 0) | AC15: =IFERROR(AA15*AB15, 0) | AF15: =IFERROR(AD15*AE15, 0) | AI15: =IFERROR(AG15*AH15, 0) | AL15: =IFERROR(AJ15*AK15, 0) | AO15: =IFERROR(AM15*AN15, 0) | AR15: =IFERROR(AP15*AQ15, 0) | AU15: =IFERROR(AS15*AT15, 0) | AX15: =IFERROR(AV15*AW15, 0) | BA15: =IFERROR(AY15*AZ15, 0) | BD15: =IFERROR(BB15*BC15, 0) | BG15: =IFERROR(BE15*BF15, 0) | BJ15: =IFERROR(BH15*BI15, 0) | BM15: =IFERROR(BK15*BL15, 0) | BP15: =IFERROR(BN15*BO15, 0) | BS15: =IFERROR(BQ15*BR15, 0) | BV15: =IFERROR(BT15*BU15, 0) | BY15: =IFERROR(BW15*BX15, 0) | CB15: =IFERROR(BZ15*CA15, 0) | CE15: =IFERROR(CC15*CD15, 0) | CH15: =IFERROR(CF15*CG15, 0) | CK15: =IFERROR(CI15*CJ15, 0) | CN15: =IFERROR(CL15*CM15, 0) | CQ15: =IFERROR(CO15*CP15, 0) | CT15: =IFERROR(CR15*CS15, 0) | CU15: =IFERROR(SUM(F15,I15,L15,O15,R15,U15,X15,AA15,AD15,AG15,AJ15,AM15,AP15,AS15,AV15,AY15,BB15,BE15,BH15,BK15,BN15,BQ15,BT15,BW15,BZ15,CC15,CF15,CI15,CL15,CO15,CR15), 0) | CV15: =IFERROR(AVERAGE(G15,J15,M15,P15,S15,V15,Y15,AB15,AE15,AH15,AK15,AN15,AQ15,AT15,AW15,AZ15,BC15,BF15,BI15,BL15,BO15,BR15,BU15,BX15,CA15,CD15,CG15,CJ15,CM15,CP15,CS15), 0) | CW15: =CU15*CV15
A16: Morcilla | B16: Kg | E16: 0 | H16: =IFERROR(F16*G16, 0) | K16: =IFERROR(I16*J16, 0) | N16: =IFERROR(L16*M16, 0) | Q16: =IFERROR(O16*P16, 0) | T16: =IFERROR(R16*S16, 0) | W16: =IFERROR(U16*V16, 0) | Z16: =IFERROR(X16*Y16, 0) | AC16: =IFERROR(AA16*AB16, 0) | AF16: =IFERROR(AD16*AE16, 0) | AI16: =IFERROR(AG16*AH16, 0) | AJ16: 5 | AK16: 20000 | AL16: 100000 | AO16: =IFERROR(AM16*AN16, 0) | AR16: =IFERROR(AP16*AQ16, 0) | AU16: =IFERROR(AS16*AT16, 0) | AX16: =IFERROR(AV16*AW16, 0) | BA16: =IFERROR(AY16*AZ16, 0) | BD16: =IFERROR(BB16*BC16, 0) | BG16: =IFERROR(BE16*BF16, 0) | BJ16: =IFERROR(BH16*BI16, 0) | BM16: =BL16*BK16 | BP16: =IFERROR(BN16*BO16, 0) | BS16: =IFERROR(BQ16*BR16, 0) | BV16: =IFERROR(BT16*BU16, 0) | BY16: =IFERROR(BW16*BX16, 0) | CB16: =IFERROR(BZ16*CA16, 0) | CE16: =IFERROR(CC16*CD16, 0) | CH16: =IFERROR(CF16*CG16, 0) | CK16: =IFERROR(CI16*CJ16, 0) | CN16: =IFERROR(CL16*CM16, 0) | CQ16: =IFERROR(CO16*CP16, 0) | CT16: =IFERROR(CR16*CS16, 0) | CU16: =IFERROR(SUM(F16,I16,L16,O16,R16,U16,X16,AA16,AD16,AG16,AJ16,AM16,AP16,AS16,AV16,AY16,BB16,BE16,BH16,BK16,BN16,BQ16,BT16,BW16,BZ16,CC16,CF16,CI16,CL16,CO16,CR16), 0) | CV16: =IFERROR(AVERAGE(G16,J16,M16,P16,S16,V16,Y16,AB16,AE16,AH16,AK16,AN16,AQ16,AT16,AW16,AZ16,BC16,BF16,BI16,BL16,BO16,BR16,BU16,BX16,CA16,CD16,CG16,CJ16,CM16,CP16,CS16), 0) | CW16: =CU16*CV16
A17: Lomo de caracho | B17: Kg | E17: 0 | H17: =IFERROR(F17*G17, 0) | K17: =IFERROR(I17*J17, 0) | N17: =IFERROR(L17*M17, 0) | Q17: =IFERROR(O17*P17, 0) | T17: =IFERROR(R17*S17, 0) | W17: =IFERROR(U17*V17, 0) | Z17: =IFERROR(X17*Y17, 0) | AC17: =IFERROR(AA17*AB17, 0) | AF17: =IFERROR(AD17*AE17, 0) | AG17: 14.5 | AH17: 44000 | AI17: 638000 | AL17: =IFERROR(AJ17*AK17, 0) | AO17: =IFERROR(AM17*AN17, 0) | AR17: =IFERROR(AP17*AQ17, 0) | AU17: =IFERROR(AS17*AT17, 0) | AX17: =IFERROR(AV17*AW17, 0) | BA17: =IFERROR(AY17*AZ17, 0) | BD17: =IFERROR(BB17*BC17, 0) | BG17: =IFERROR(BE17*BF17, 0) | BJ17: =IFERROR(BH17*BI17, 0) | BM17: =IFERROR(BK17*BL17, 0) | BP17: =IFERROR(BN17*BO17, 0) | BS17: =IFERROR(BQ17*BR17, 0) | BT17: 6.71 | BU17: 50900 | BV17: 341539 | BY17: =IFERROR(BW17*BX17, 0) | CB17: =IFERROR(BZ17*CA17, 0) | CE17: =IFERROR(CC17*CD17, 0) | CH17: =IFERROR(CF17*CG17, 0) | CK17: =IFERROR(CI17*CJ17, 0) | CN17: =IFERROR(CL17*CM17, 0) | CQ17: =IFERROR(CO17*CP17, 0) | CT17: =IFERROR(CR17*CS17, 0) | CU17: =IFERROR(SUM(F17,I17,L17,O17,R17,U17,X17,AA17,AD17,AG17,AJ17,AM17,AP17,AS17,AV17,AY17,BB17,BE17,BH17,BK17,BN17,BQ17,BT17,BW17,BZ17,CC17,CF17,CI17,CL17,CO17,CR17), 0) | CV17: =IFERROR(AVERAGE(G17,J17,M17,P17,S17,V17,Y17,AB17,AE17,AH17,AK17,AN17,AQ17,AT17,AW17,AZ17,BC17,BF17,BI17,BL17,BO17,BR17,BU17,BX17,CA17,CD17,CG17,CJ17,CM17,CP17,CS17), 0) | CW17: =CU17*CV17
A18: Chorizo Premium | B18: Kg | E18: 0 | H18: =IFERROR(F18*G18, 0) | K18: =IFERROR(I18*J18, 0) | N18: =IFERROR(L18*M18, 0) | O18: 2 | P18: 46000 | Q18: 92000 | T18: =IFERROR(R18*S18, 0) | W18: =IFERROR(U18*V18, 0) | Z18: =IFERROR(X18*Y18, 0) | AC18: =IFERROR(AA18*AB18, 0) | AF18: =IFERROR(AD18*AE18, 0) | AG18: 2 | AH18: 46000 | AI18: 92000 | AL18: =IFERROR(AJ18*AK18, 0) | AO18: =IFERROR(AM18*AN18, 0) | AR18: =IFERROR(AP18*AQ18, 0) | AU18: =IFERROR(AS18*AT18, 0) | AV18: 2 | AW18: 46000 | AX18: 92000 | BA18: =IFERROR(AY18*AZ18, 0) | BD18: =IFERROR(BB18*BC18, 0) | BG18: =IFERROR(BE18*BF18, 0) | BJ18: =IFERROR(BH18*BI18, 0) | BK18: 5 | BL18: 46000 | BM18: 230000 | BP18: =IFERROR(BN18*BO18, 0) | BS18: =IFERROR(BQ18*BR18, 0) | BV18: =IFERROR(BT18*BU18, 0) | BY18: =IFERROR(BW18*BX18, 0) | CB18: =IFERROR(BZ18*CA18, 0) | CE18: =IFERROR(CC18*CD18, 0) | CH18: =IFERROR(CF18*CG18, 0) | CK18: =IFERROR(CI18*CJ18, 0) | CN18: =IFERROR(CL18*CM18, 0) | CQ18: =IFERROR(CO18*CP18, 0) | CT18: =IFERROR(CR18*CS18, 0) | CU18: =IFERROR(SUM(F18,I18,L18,O18,R18,U18,X18,AA18,AD18,AG18,AJ18,AM18,AP18,AS18,AV18,AY18,BB18,BE18,BH18,BK18,BN18,BQ18,BT18,BW18,BZ18,CC18,CF18,CI18,CL18,CO18,CR18), 0) | CV18: =IFERROR(AVERAGE(G18,J18,M18,P18,S18,V18,Y18,AB18,AE18,AH18,AK18,AN18,AQ18,AT18,AW18,AZ18,BC18,BF18,BI18,BL18,BO18,BR18,BU18,BX18,CA18,CD18,CG18,CJ18,CM18,CP18,CS18), 0) | CW18: =CU18*CV18
A19: Churrasco | B19: Kg | E19: 0 | H19: =IFERROR(F19*G19, 0) | K19: =IFERROR(I19*J19, 0) | N19: =IFERROR(L19*M19, 0) | Q19: =IFERROR(O19*P19, 0) | T19: =IFERROR(R19*S19, 0) | W19: =IFERROR(U19*V19, 0) | Z19: =IFERROR(X19*Y19, 0) | AC19: =IFERROR(AA19*AB19, 0) | AF19: =IFERROR(AD19*AE19, 0) | AI19: =IFERROR(AG19*AH19, 0) | AL19: =IFERROR(AJ19*AK19, 0) | AO19: =IFERROR(AM19*AN19, 0) | AR19: =IFERROR(AP19*AQ19, 0) | AU19: =IFERROR(AS19*AT19, 0) | AX19: =IFERROR(AV19*AW19, 0) | BA19: =IFERROR(AY19*AZ19, 0) | BD19: =IFERROR(BB19*BC19, 0) | BG19: =IFERROR(BE19*BF19, 0) | BJ19: =IFERROR(BH19*BI19, 0) | BM19: =IFERROR(BK19*BL19, 0) | BP19: =IFERROR(BN19*BO19, 0) | BS19: =IFERROR(BQ19*BR19, 0) | BV19: =IFERROR(BT19*BU19, 0) | BY19: =IFERROR(BW19*BX19, 0) | CB19: =IFERROR(BZ19*CA19, 0) | CE19: =IFERROR(CC19*CD19, 0) | CH19: =IFERROR(CF19*CG19, 0) | CK19: =IFERROR(CI19*CJ19, 0) | CN19: =IFERROR(CL19*CM19, 0) | CQ19: =IFERROR(CO19*CP19, 0) | CT19: =IFERROR(CR19*CS19, 0) | CU19: =IFERROR(SUM(F19,I19,L19,O19,R19,U19,X19,AA19,AD19,AG19,AJ19,AM19,AP19,AS19,AV19,AY19,BB19,BE19,BH19,BK19,BN19,BQ19,BT19,BW19,BZ19,CC19,CF19,CI19,CL19,CO19,CR19), 0) | CV19: =IFERROR(AVERAGE(G19,J19,M19,P19,S19,V19,Y19,AB19,AE19,AH19,AK19,AN19,AQ19,AT19,AW19,AZ19,BC19,BF19,BI19,BL19,BO19,BR19,BU19,BX19,CA19,CD19,CG19,CJ19,CM19,CP19,CS19), 0) | CW19: =CU19*CV19
A20: Costilla ahumada | B20: Kg | E20: 0 | H20: =IFERROR(F20*G20, 0) | K20: =IFERROR(I20*J20, 0) | N20: =IFERROR(L20*M20, 0) | Q20: =IFERROR(O20*P20, 0) | R20: 8 | S20: 22900 | T20: 183200 | W20: =IFERROR(U20*V20, 0) | Z20: =IFERROR(X20*Y20, 0) | AC20: =IFERROR(AA20*AB20, 0) | AF20: =IFERROR(AD20*AE20, 0) | AI20: =IFERROR(AG20*AH20, 0) | AL20: =IFERROR(AJ20*AK20, 0) | AO20: =IFERROR(AM20*AN20, 0) | AR20: =IFERROR(AP20*AQ20, 0) | AU20: =IFERROR(AS20*AT20, 0) | AX20: =IFERROR(AV20*AW20, 0) | BA20: =IFERROR(AY20*AZ20, 0) | BD20: =IFERROR(BB20*BC20, 0) | BG20: =IFERROR(BE20*BF20, 0) | BJ20: =IFERROR(BH20*BI20, 0) | BM20: =IFERROR(BK20*BL20, 0) | BP20: =IFERROR(BN20*BO20, 0) | BS20: =IFERROR(BQ20*BR20, 0) | BV20: =IFERROR(BT20*BU20, 0) | BY20: =IFERROR(BW20*BX20, 0) | CB20: =IFERROR(BZ20*CA20, 0) | CE20: =IFERROR(CC20*CD20, 0) | CH20: =IFERROR(CF20*CG20, 0) | CK20: =IFERROR(CI20*CJ20, 0) | CN20: =IFERROR(CL20*CM20, 0) | CQ20: =IFERROR(CO20*CP20, 0) | CT20: =IFERROR(CR20*CS20, 0) | CU20: =IFERROR(SUM(F20,I20,L20,O20,R20,U20,X20,AA20,AD20,AG20,AJ20,AM20,AP20,AS20,AV20,AY20,BB20,BE20,BH20,BK20,BN20,BQ20,BT20,BW20,BZ20,CC20,CF20,CI20,CL20,CO20,CR20), 0) | CV20: =IFERROR(AVERAGE(G20,J20,M20,P20,S20,V20,Y20,AB20,AE20,AH20,AK20,AN20,AQ20,AT20,AW20,AZ20,BC20,BF20,BI20,BL20,BO20,BR20,BU20,BX20,CA20,CD20,CG20,CJ20,CM20,CP20,CS20), 0) | CW20: =CU20*CV20
A21: Costilla corte americano | B21: Kg | E21: 0 | H21: =IFERROR(F21*G21, 0) | K21: =IFERROR(I21*J21, 0) | N21: =IFERROR(L21*M21, 0) | Q21: =IFERROR(O21*P21, 0) | T21: =IFERROR(R21*S21, 0) | W21: =IFERROR(U21*V21, 0) | Z21: =IFERROR(X21*Y21, 0) | AC21: =IFERROR(AA21*AB21, 0) | AF21: =IFERROR(AD21*AE21, 0) | AI21: =IFERROR(AG21*AH21, 0) | AL21: =IFERROR(AJ21*AK21, 0) | AO21: =IFERROR(AM21*AN21, 0) | AR21: =IFERROR(AP21*AQ21, 0) | AU21: =IFERROR(AS21*AT21, 0) | AX21: =IFERROR(AV21*AW21, 0) | BA21: =IFERROR(AY21*AZ21, 0) | BD21: =IFERROR(BB21*BC21, 0) | BG21: =IFERROR(BE21*BF21, 0) | BJ21: =IFERROR(BH21*BI21, 0) | BM21: =IFERROR(BK21*BL21, 0) | BP21: =IFERROR(BN21*BO21, 0) | BS21: =IFERROR(BQ21*BR21, 0) | BV21: =IFERROR(BT21*BU21, 0) | BY21: =IFERROR(BW21*BX21, 0) | CB21: =IFERROR(BZ21*CA21, 0) | CE21: =IFERROR(CC21*CD21, 0) | CH21: =IFERROR(CF21*CG21, 0) | CK21: =IFERROR(CI21*CJ21, 0) | CN21: =IFERROR(CL21*CM21, 0) | CQ21: =IFERROR(CO21*CP21, 0) | CT21: =IFERROR(CR21*CS21, 0) | CU21: =IFERROR(SUM(F21,I21,L21,O21,R21,U21,X21,AA21,AD21,AG21,AJ21,AM21,AP21,AS21,AV21,AY21,BB21,BE21,BH21,BK21,BN21,BQ21,BT21,BW21,BZ21,CC21,CF21,CI21,CL21,CO21,CR21), 0) | CV21: =IFERROR(AVERAGE(G21,J21,M21,P21,S21,V21,Y21,AB21,AE21,AH21,AK21,AN21,AQ21,AT21,AW21,AZ21,BC21,BF21,BI21,BL21,BO21,BR21,BU21,BX21,CA21,CD21,CG21,CJ21,CM21,CP21,CS21), 0) | CW21: =CU21*CV21
A22: Costilla de cerdo especial | B22: Kg | E22: 0 | H22: =IFERROR(F22*G22, 0) | K22: =IFERROR(I22*J22, 0) | N22: =IFERROR(L22*M22, 0) | Q22: =IFERROR(O22*P22, 0) | T22: =IFERROR(R22*S22, 0) | W22: =IFERROR(U22*V22, 0) | X22: 28.1 | Y22: 16700 | Z22: 469270 | AC22: =IFERROR(AA22*AB22, 0) | AF22: =IFERROR(AD22*AE22, 0) | AI22: =IFERROR(AG22*AH22, 0) | AL22: =IFERROR(AJ22*AK22, 0) | AO22: =IFERROR(AM22*AN22, 0) | AR22: =IFERROR(AP22*AQ22, 0) | AU22: =IFERROR(AS22*AT22, 0) | AV22: 28.1 | AW22: 15900 | AX22: 446790 | BA22: =IFERROR(AY22*AZ22, 0) | BD22: =IFERROR(BB22*BC22, 0) | BE22: 20 | BF22: 18200 | BG22: 364000 | BJ22: =IFERROR(BH22*BI22, 0) | BM22: =IFERROR(BK22*BL22, 0) | BP22: =IFERROR(BN22*BO22, 0) | BS22: =IFERROR(BQ22*BR22, 0) | BT22: 26.1 | BU22: 15400 | BV22: 401940 | BY22: =IFERROR(BW22*BX22, 0) | CB22: =IFERROR(BZ22*CA22, 0) | CE22: =IFERROR(CC22*CD22, 0) | CH22: =IFERROR(CF22*CG22, 0) | CK22: =IFERROR(CI22*CJ22, 0) | CN22: =IFERROR(CL22*CM22, 0) | CQ22: =IFERROR(CO22*CP22, 0) | CT22: =IFERROR(CR22*CS22, 0) | CU22: =IFERROR(SUM(F22,I22,L22,O22,R22,U22,X22,AA22,AD22,AG22,AJ22,AM22,AP22,AS22,AV22,AY22,BB22,BE22,BH22,BK22,BN22,BQ22,BT22,BW22,BZ22,CC22,CF22,CI22,CL22,CO22,CR22), 0) | CV22: =IFERROR(AVERAGE(G22,J22,M22,P22,S22,V22,Y22,AB22,AE22,AH22,AK22,AN22,AQ22,AT22,AW22,AZ22,BC22,BF22,BI22,BL22,BO22,BR22,BU22,BX22,CA22,CD22,CG22,CJ22,CM22,CP22,CS22), 0) | CW22: =CU22*CV22
A23: Costilla de res | B23: Kg | E23: 0 | H23: =IFERROR(F23*G23, 0) | K23: =IFERROR(I23*J23, 0) | N23: =IFERROR(L23*M23, 0) | Q23: =IFERROR(O23*P23, 0) | T23: =IFERROR(R23*S23, 0) | W23: =IFERROR(U23*V23, 0) | Z23: =IFERROR(X23*Y23, 0) | AC23: =IFERROR(AA23*AB23, 0) | AF23: =IFERROR(AD23*AE23, 0) | AI23: =IFERROR(AG23*AH23, 0) | AL23: =IFERROR(AJ23*AK23, 0) | AO23: =IFERROR(AM23*AN23, 0) | AR23: =IFERROR(AP23*AQ23, 0) | AU23: =IFERROR(AS23*AT23, 0) | AX23: =IFERROR(AV23*AW23, 0) | BA23: =IFERROR(AY23*AZ23, 0) | BD23: =IFERROR(BB23*BC23, 0) | BG23: =IFERROR(BE23*BF23, 0) | BJ23: =IFERROR(BH23*BI23, 0) | BM23: =IFERROR(BK23*BL23, 0) | BN23: 20.55 | BO23: 22000 | BP23: 452100 | BS23: =IFERROR(BQ23*BR23, 0) | BV23: =IFERROR(BT23*BU23, 0) | BY23: =IFERROR(BW23*BX23, 0) | CB23: =IFERROR(BZ23*CA23, 0) | CE23: =IFERROR(CC23*CD23, 0) | CH23: =IFERROR(CF23*CG23, 0) | CK23: =IFERROR(CI23*CJ23, 0) | CN23: =IFERROR(CL23*CM23, 0) | CQ23: =IFERROR(CO23*CP23, 0) | CT23: =IFERROR(CR23*CS23, 0) | CU23: =IFERROR(SUM(F23,I23,L23,O23,R23,U23,X23,AA23,AD23,AG23,AJ23,AM23,AP23,AS23,AV23,AY23,BB23,BE23,BH23,BK23,BN23,BQ23,BT23,BW23,BZ23,CC23,CF23,CI23,CL23,CO23,CR23), 0) | CV23: =IFERROR(AVERAGE(G23,J23,M23,P23,S23,V23,Y23,AB23,AE23,AH23,AK23,AN23,AQ23,AT23,AW23,AZ23,BC23,BF23,BI23,BL23,BO23,BR23,BU23,BX23,CA23,CD23,CG23,CJ23,CM23,CP23,CS23), 0) | CW23: =CU23*CV23
A24: Costilla san luis | B24: Kg | E24: 0 | H24: =IFERROR(F24*G24, 0) | K24: =IFERROR(I24*J24, 0) | N24: =IFERROR(L24*M24, 0) | Q24: =IFERROR(O24*P24, 0) | T24: =IFERROR(R24*S24, 0) | W24: =IFERROR(U24*V24, 0) | Z24: =IFERROR(X24*Y24, 0) | AC24: =IFERROR(AA24*AB24, 0) | AF24: =IFERROR(AD24*AE24, 0) | AI24: =IFERROR(AG24*AH24, 0) | AL24: =IFERROR(AJ24*AK24, 0) | AO24: =IFERROR(AM24*AN24, 0) | AR24: =IFERROR(AP24*AQ24, 0) | AU24: =IFERROR(AS24*AT24, 0) | AX24: =IFERROR(AV24*AW24, 0) | BA24: =IFERROR(AY24*AZ24, 0) | BD24: =IFERROR(BB24*BC24, 0) | BG24: =IFERROR(BE24*BF24, 0) | BJ24: =IFERROR(BH24*BI24, 0) | BM24: =IFERROR(BK24*BL24, 0) | BP24: =IFERROR(BN24*BO24, 0) | BS24: =IFERROR(BQ24*BR24, 0) | BV24: =IFERROR(BT24*BU24, 0) | BY24: =IFERROR(BW24*BX24, 0) | CB24: =IFERROR(BZ24*CA24, 0) | CE24: =IFERROR(CC24*CD24, 0) | CH24: =IFERROR(CF24*CG24, 0) | CK24: =IFERROR(CI24*CJ24, 0) | CN24: =IFERROR(CL24*CM24, 0) | CQ24: =IFERROR(CO24*CP24, 0) | CT24: =IFERROR(CR24*CS24, 0) | CU24: =IFERROR(SUM(F24,I24,L24,O24,R24,U24,X24,AA24,AD24,AG24,AJ24,AM24,AP24,AS24,AV24,AY24,BB24,BE24,BH24,BK24,BN24,BQ24,BT24,BW24,BZ24,CC24,CF24,CI24,CL24,CO24,CR24), 0) | CV24: =IFERROR(AVERAGE(G24,J24,M24,P24,S24,V24,Y24,AB24,AE24,AH24,AK24,AN24,AQ24,AT24,AW24,AZ24,BC24,BF24,BI24,BL24,BO24,BR24,BU24,BX24,CA24,CD24,CG24,CJ24,CM24,CP24,CS24), 0) | CW24: =CU24*CV24
A25: Costilla san luis jr | B25: Kg | E25: 0 | H25: =IFERROR(F25*G25, 0) | K25: =IFERROR(I25*J25, 0) | N25: =IFERROR(L25*M25, 0) | O25: 20.2 | P25: 22000 | Q25: 444400 | T25: =IFERROR(R25*S25, 0) | W25: =IFERROR(U25*V25, 0) | X25: 48.66 | Y25: 21900 | Z25: 1065654 | AC25: =IFERROR(AA25*AB25, 0) | AF25: =IFERROR(AD25*AE25, 0) | AI25: =IFERROR(AG25*AH25, 0) | AL25: =IFERROR(AJ25*AK25, 0) | AO25: =IFERROR(AM25*AN25, 0) | AR25: =IFERROR(AP25*AQ25, 0) | AU25: =IFERROR(AS25*AT25, 0) | AX25: =IFERROR(AV25*AW25, 0) | BA25: =IFERROR(AY25*AZ25, 0) | BD25: =IFERROR(BB25*BC25, 0) | BG25: =IFERROR(BE25*BF25, 0) | BJ25: =IFERROR(BH25*BI25, 0) | BM25: =IFERROR(BK25*BL25, 0) | BP25: =IFERROR(BN25*BO25, 0) | BS25: =IFERROR(BQ25*BR25, 0) | BV25: =IFERROR(BT25*BU25, 0) | BY25: =IFERROR(BW25*BX25, 0) | CB25: =IFERROR(BZ25*CA25, 0) | CE25: =IFERROR(CC25*CD25, 0) | CH25: =IFERROR(CF25*CG25, 0) | CK25: =IFERROR(CI25*CJ25, 0) | CN25: =IFERROR(CL25*CM25, 0) | CQ25: =IFERROR(CO25*CP25, 0) | CT25: =IFERROR(CR25*CS25, 0) | CU25: =IFERROR(SUM(F25,I25,L25,O25,R25,U25,X25,AA25,AD25,AG25,AJ25,AM25,AP25,AS25,AV25,AY25,BB25,BE25,BH25,BK25,BN25,BQ25,BT25,BW25,BZ25,CC25,CF25,CI25,CL25,CO25,CR25), 0) | CV25: =IFERROR(AVERAGE(G25,J25,M25,P25,S25,V25,Y25,AB25,AE25,AH25,AK25,AN25,AQ25,AT25,AW25,AZ25,BC25,BF25,BI25,BL25,BO25,BR25,BU25,BX25,CA25,CD25,CG25,CJ25,CM25,CP25,CS25), 0) | CW25: =CU25*CV25
A26: Empella | B26: Kg | E26: 0 | H26: =IFERROR(F26*G26, 0) | K26: =IFERROR(I26*J26, 0) | N26: =IFERROR(L26*M26, 0) | Q26: =IFERROR(O26*P26, 0) | T26: =IFERROR(R26*S26, 0) | W26: =IFERROR(U26*V26, 0) | Z26: =IFERROR(X26*Y26, 0) | AC26: =IFERROR(AA26*AB26, 0) | AF26: =IFERROR(AD26*AE26, 0) | AI26: =IFERROR(AG26*AH26, 0) | AL26: =IFERROR(AJ26*AK26, 0) | AO26: =IFERROR(AM26*AN26, 0) | AR26: =IFERROR(AP26*AQ26, 0) | AU26: =IFERROR(AS26*AT26, 0) | AX26: =IFERROR(AV26*AW26, 0) | BA26: =IFERROR(AY26*AZ26, 0) | BD26: =IFERROR(BB26*BC26, 0) | BG26: =IFERROR(BE26*BF26, 0) | BJ26: =IFERROR(BH26*BI26, 0) | BM26: =IFERROR(BK26*BL26, 0) | BP26: =IFERROR(BN26*BO26, 0) | BS26: =IFERROR(BQ26*BR26, 0) | BV26: =IFERROR(BT26*BU26, 0) | BY26: =IFERROR(BW26*BX26, 0) | CB26: =IFERROR(BZ26*CA26, 0) | CE26: =IFERROR(CC26*CD26, 0) | CH26: =IFERROR(CF26*CG26, 0) | CK26: =IFERROR(CI26*CJ26, 0) | CN26: =IFERROR(CL26*CM26, 0) | CQ26: =IFERROR(CO26*CP26, 0) | CT26: =IFERROR(CR26*CS26, 0) | CU26: =IFERROR(SUM(F26,I26,L26,O26,R26,U26,X26,AA26,AD26,AG26,AJ26,AM26,AP26,AS26,AV26,AY26,BB26,BE26,BH26,BK26,BN26,BQ26,BT26,BW26,BZ26,CC26,CF26,CI26,CL26,CO26,CR26), 0) | CV26: =IFERROR(AVERAGE(G26,J26,M26,P26,S26,V26,Y26,AB26,AE26,AH26,AK26,AN26,AQ26,AT26,AW26,AZ26,BC26,BF26,BI26,BL26,BO26,BR26,BU26,BX26,CA26,CD26,CG26,CJ26,CM26,CP26,CS26), 0) | CW26: =CU26*CV26
A27: Espinazo de cerdo | B27: Kg | E27: 0 | H27: =IFERROR(F27*G27, 0) | K27: =IFERROR(I27*J27, 0) | N27: =IFERROR(L27*M27, 0) | Q27: =IFERROR(O27*P27, 0) | T27: =IFERROR(R27*S27, 0) | U27: 3.036 | V27: 7350 | W27: 22315 | Z27: =IFERROR(X27*Y27, 0) | AC27: =IFERROR(AA27*AB27, 0) | AF27: =IFERROR(AD27*AE27, 0) | AI27: =IFERROR(AG27*AH27, 0) | AL27: =IFERROR(AJ27*AK27, 0) | AO27: =IFERROR(AM27*AN27, 0) | AR27: =IFERROR(AP27*AQ27, 0) | AU27: =IFERROR(AS27*AT27, 0) | AX27: =IFERROR(AV27*AW27, 0) | BA27: =IFERROR(AY27*AZ27, 0) | BD27: =IFERROR(BB27*BC27, 0) | BG27: =IFERROR(BE27*BF27, 0) | BJ27: =IFERROR(BH27*BI27, 0) | BM27: =IFERROR(BK27*BL27, 0) | BP27: =IFERROR(BN27*BO27, 0) | BQ27: 3.058 | BR27: 9799 | BS27: 30066 | BV27: =IFERROR(BT27*BU27, 0) | BY27: =IFERROR(BW27*BX27, 0) | CB27: =IFERROR(BZ27*CA27, 0) | CE27: =IFERROR(CC27*CD27, 0) | CH27: =IFERROR(CF27*CG27, 0) | CK27: =IFERROR(CI27*CJ27, 0) | CN27: =IFERROR(CL27*CM27, 0) | CQ27: =IFERROR(CO27*CP27, 0) | CT27: =IFERROR(CR27*CS27, 0) | CU27: =IFERROR(SUM(F27,I27,L27,O27,R27,U27,X27,AA27,AD27,AG27,AJ27,AM27,AP27,AS27,AV27,AY27,BB27,BE27,BH27,BK27,BN27,BQ27,BT27,BW27,BZ27,CC27,CF27,CI27,CL27,CO27,CR27), 0) | CV27: =IFERROR(AVERAGE(G27,J27,M27,P27,S27,V27,Y27,AB27,AE27,AH27,AK27,AN27,AQ27,AT27,AW27,AZ27,BC27,BF27,BI27,BL27,BO27,BR27,BU27,BX27,CA27,CD27,CG27,CJ27,CM27,CP27,CS27), 0) | CW27: =CU27*CV27
A28: Filete de pollo x 120 | B28: Und | E28: 0 | H28: =IFERROR(F28*G28, 0) | K28: =IFERROR(I28*J28, 0) | N28: =IFERROR(L28*M28, 0) | Q28: =IFERROR(O28*P28, 0) | T28: =IFERROR(R28*S28, 0) | W28: =IFERROR(U28*V28, 0) | Z28: =IFERROR(X28*Y28, 0) | AC28: =IFERROR(AA28*AB28, 0) | AF28: =IFERROR(AD28*AE28, 0) | AI28: =IFERROR(AG28*AH28, 0) | AL28: =IFERROR(AJ28*AK28, 0) | AO28: =IFERROR(AM28*AN28, 0) | AR28: =IFERROR(AP28*AQ28, 0) | AU28: =IFERROR(AS28*AT28, 0) | AX28: =IFERROR(AV28*AW28, 0) | BA28: =IFERROR(AY28*AZ28, 0) | BD28: =IFERROR(BB28*BC28, 0) | BG28: =IFERROR(BE28*BF28, 0) | BJ28: =IFERROR(BH28*BI28, 0) | BM28: =IFERROR(BK28*BL28, 0) | BP28: =IFERROR(BN28*BO28, 0) | BS28: =IFERROR(BQ28*BR28, 0) | BV28: =IFERROR(BT28*BU28, 0) | BY28: =IFERROR(BW28*BX28, 0) | CB28: =IFERROR(BZ28*CA28, 0) | CE28: =IFERROR(CC28*CD28, 0) | CH28: =IFERROR(CF28*CG28, 0) | CK28: =IFERROR(CI28*CJ28, 0) | CN28: =IFERROR(CL28*CM28, 0) | CQ28: =IFERROR(CO28*CP28, 0) | CT28: =IFERROR(CR28*CS28, 0) | CU28: =IFERROR(SUM(F28,I28,L28,O28,R28,U28,X28,AA28,AD28,AG28,AJ28,AM28,AP28,AS28,AV28,AY28,BB28,BE28,BH28,BK28,BN28,BQ28,BT28,BW28,BZ28,CC28,CF28,CI28,CL28,CO28,CR28), 0) | CV28: =IFERROR(AVERAGE(G28,J28,M28,P28,S28,V28,Y28,AB28,AE28,AH28,AK28,AN28,AQ28,AT28,AW28,AZ28,BC28,BF28,BI28,BL28,BO28,BR28,BU28,BX28,CA28,CD28,CG28,CJ28,CM28,CP28,CS28), 0) | CW28: =CU28*CV28
A29: Filete de pollo x 350 | B29: Kg | E29: 0 | H29: =IFERROR(F29*G29, 0) | K29: =IFERROR(I29*J29, 0) | L29: 10.36 | M29: 18500 | N29: 191660 | Q29: =IFERROR(O29*P29, 0) | R29: 4 | S29: 40250 | T29: 161000 | U29: 24.9 | V29: 18500 | W29: 460650 | Z29: =IFERROR(X29*Y29, 0) | AC29: =IFERROR(AA29*AB29, 0) | AF29: =IFERROR(AD29*AE29, 0) | AG29: 24.7 | AH29: 18500 | AI29: 456950 | AL29: =IFERROR(AJ29*AK29, 0) | AO29: =IFERROR(AM29*AN29, 0) | AR29: =IFERROR(AP29*AQ29, 0) | AS29: 10.6 | AT29: 18500 | AU29: 196100 | AX29: =IFERROR(AV29*AW29, 0) | BA29: =IFERROR(AY29*AZ29, 0) | BD29: =IFERROR(BB29*BC29, 0) | BE29: 24.3 | BF29: 18500 | BG29: 449550 | BJ29: =IFERROR(BH29*BI29, 0) | BM29: =IFERROR(BK29*BL29, 0) | BP29: =IFERROR(BN29*BO29, 0) | BS29: =IFERROR(BQ29*BR29, 0) | BV29: =IFERROR(BT29*BU29, 0) | BY29: =IFERROR(BW29*BX29, 0) | CB29: =IFERROR(BZ29*CA29, 0) | CE29: =IFERROR(CC29*CD29, 0) | CH29: =IFERROR(CF29*CG29, 0) | CK29: =IFERROR(CI29*CJ29, 0) | CN29: =IFERROR(CL29*CM29, 0) | CQ29: =IFERROR(CO29*CP29, 0) | CT29: =IFERROR(CR29*CS29, 0) | CU29: =IFERROR(SUM(F29,I29,L29,O29,R29,U29,X29,AA29,AD29,AG29,AJ29,AM29,AP29,AS29,AV29,AY29,BB29,BE29,BH29,BK29,BN29,BQ29,BT29,BW29,BZ29,CC29,CF29,CI29,CL29,CO29,CR29), 0) | CV29: =IFERROR(AVERAGE(G29,J29,M29,P29,S29,V29,Y29,AB29,AE29,AH29,AK29,AN29,AQ29,AT29,AW29,AZ29,BC29,BF29,BI29,BL29,BO29,BR29,BU29,BX29,CA29,CD29,CG29,CJ29,CM29,CP29,CS29), 0) | CW29: =CU29*CV29
A30: Filete de pollo x 400 | B30: Kg | E30: 0 | H30: =IFERROR(F30*G30, 0) | K30: =IFERROR(I30*J30, 0) | N30: =IFERROR(L30*M30, 0) | Q30: =IFERROR(O30*P30, 0) | T30: =IFERROR(R30*S30, 0) | W30: =IFERROR(U30*V30, 0) | Z30: =IFERROR(X30*Y30, 0) | AC30: =IFERROR(AA30*AB30, 0) | AF30: =IFERROR(AD30*AE30, 0) | AI30: =IFERROR(AG30*AH30, 0) | AL30: =IFERROR(AJ30*AK30, 0) | AO30: =IFERROR(AM30*AN30, 0) | AR30: =IFERROR(AP30*AQ30, 0) | AU30: =IFERROR(AS30*AT30, 0) | AX30: =IFERROR(AV30*AW30, 0) | BA30: =IFERROR(AY30*AZ30, 0) | BD30: =IFERROR(BB30*BC30, 0) | BG30: =IFERROR(BE30*BF30, 0) | BJ30: =IFERROR(BH30*BI30, 0) | BM30: =IFERROR(BK30*BL30, 0) | BP30: =IFERROR(BN30*BO30, 0) | BS30: =IFERROR(BQ30*BR30, 0) | BV30: =IFERROR(BT30*BU30, 0) | BY30: =IFERROR(BW30*BX30, 0) | CB30: =IFERROR(BZ30*CA30, 0) | CE30: =IFERROR(CC30*CD30, 0) | CH30: =IFERROR(CF30*CG30, 0) | CK30: =IFERROR(CI30*CJ30, 0) | CN30: =IFERROR(CL30*CM30, 0) | CQ30: =IFERROR(CO30*CP30, 0) | CT30: =IFERROR(CR30*CS30, 0) | CU30: =IFERROR(SUM(F30,I30,L30,O30,R30,U30,X30,AA30,AD30,AG30,AJ30,AM30,AP30,AS30,AV30,AY30,BB30,BE30,BH30,BK30,BN30,BQ30,BT30,BW30,BZ30,CC30,CF30,CI30,CL30,CO30,CR30), 0) | CV30: =IFERROR(AVERAGE(G30,J30,M30,P30,S30,V30,Y30,AB30,AE30,AH30,AK30,AN30,AQ30,AT30,AW30,AZ30,BC30,BF30,BI30,BL30,BO30,BR30,BU30,BX30,CA30,CD30,CG30,CJ30,CM30,CP30,CS30), 0) | CW30: =CU30*CV30
A31: Filete de pollox 320 gr | B31: Kg | E31: 0 | H31: =IFERROR(F31*G31, 0) | K31: =IFERROR(I31*J31, 0) | N31: =IFERROR(L31*M31, 0) | Q31: =IFERROR(O31*P31, 0) | T31: =IFERROR(R31*S31, 0) | W31: =IFERROR(U31*V31, 0) | Z31: =IFERROR(X31*Y31, 0) | AC31: =IFERROR(AA31*AB31, 0) | AF31: =IFERROR(AD31*AE31, 0) | AI31: =IFERROR(AG31*AH31, 0) | AL31: =IFERROR(AJ31*AK31, 0) | AO31: =IFERROR(AM31*AN31, 0) | AR31: =IFERROR(AP31*AQ31, 0) | AU31: =IFERROR(AS31*AT31, 0) | AX31: =IFERROR(AV31*AW31, 0) | BA31: =IFERROR(AY31*AZ31, 0) | BD31: =IFERROR(BB31*BC31, 0) | BG31: =IFERROR(BE31*BF31, 0) | BJ31: =IFERROR(BH31*BI31, 0) | BM31: =IFERROR(BK31*BL31, 0) | BP31: =IFERROR(BN31*BO31, 0) | BS31: =IFERROR(BQ31*BR31, 0) | BV31: =IFERROR(BT31*BU31, 0) | BY31: =IFERROR(BW31*BX31, 0) | CB31: =IFERROR(BZ31*CA31, 0) | CE31: =IFERROR(CC31*CD31, 0) | CH31: =IFERROR(CF31*CG31, 0) | CK31: =IFERROR(CI31*CJ31, 0) | CN31: =IFERROR(CL31*CM31, 0) | CQ31: =IFERROR(CO31*CP31, 0) | CT31: =IFERROR(CR31*CS31, 0) | CU31: =IFERROR(SUM(F31,I31,L31,O31,R31,U31,X31,AA31,AD31,AG31,AJ31,AM31,AP31,AS31,AV31,AY31,BB31,BE31,BH31,BK31,BN31,BQ31,BT31,BW31,BZ31,CC31,CF31,CI31,CL31,CO31,CR31), 0) | CV31: =IFERROR(AVERAGE(G31,J31,M31,P31,S31,V31,Y31,AB31,AE31,AH31,AK31,AN31,AQ31,AT31,AW31,AZ31,BC31,BF31,BI31,BL31,BO31,BR31,BU31,BX31,CA31,CD31,CG31,CJ31,CM31,CP31,CS31), 0) | CW31: =CU31*CV31
A32: Francesa | B32: Paq | E32: 0 | H32: =IFERROR(F32*G32, 0) | K32: =IFERROR(I32*J32, 0) | N32: =IFERROR(L32*M32, 0) | Q32: =IFERROR(O32*P32, 0) | T32: =IFERROR(R32*S32, 0) | W32: =IFERROR(U32*V32, 0) | Z32: =IFERROR(X32*Y32, 0) | AC32: =IFERROR(AA32*AB32, 0) | AF32: =IFERROR(AD32*AE32, 0) | AI32: =IFERROR(AG32*AH32, 0) | AL32: =IFERROR(AJ32*AK32, 0) | AO32: =IFERROR(AM32*AN32, 0) | AR32: =IFERROR(AP32*AQ32, 0) | AU32: =IFERROR(AS32*AT32, 0) | AX32: =IFERROR(AV32*AW32, 0) | BA32: =IFERROR(AY32*AZ32, 0) | BD32: =IFERROR(BB32*BC32, 0) | BG32: =IFERROR(BE32*BF32, 0) | BJ32: =IFERROR(BH32*BI32, 0) | BM32: =IFERROR(BK32*BL32, 0) | BP32: =IFERROR(BN32*BO32, 0) | BS32: =IFERROR(BQ32*BR32, 0) | BV32: =IFERROR(BT32*BU32, 0) | BY32: =IFERROR(BW32*BX32, 0) | CB32: =IFERROR(BZ32*CA32, 0) | CE32: =IFERROR(CC32*CD32, 0) | CH32: =IFERROR(CF32*CG32, 0) | CK32: =IFERROR(CI32*CJ32, 0) | CN32: =IFERROR(CL32*CM32, 0) | CQ32: =IFERROR(CO32*CP32, 0) | CT32: =IFERROR(CR32*CS32, 0) | CU32: =IFERROR(SUM(F32,I32,L32,O32,R32,U32,X32,AA32,AD32,AG32,AJ32,AM32,AP32,AS32,AV32,AY32,BB32,BE32,BH32,BK32,BN32,BQ32,BT32,BW32,BZ32,CC32,CF32,CI32,CL32,CO32,CR32), 0) | CV32: =IFERROR(AVERAGE(G32,J32,M32,P32,S32,V32,Y32,AB32,AE32,AH32,AK32,AN32,AQ32,AT32,AW32,AZ32,BC32,BF32,BI32,BL32,BO32,BR32,BU32,BX32,CA32,CD32,CG32,CJ32,CM32,CP32,CS32), 0) | CW32: =CU32*CV32
A33: Gallina | B33: Kg | E33: 0 | H33: =IFERROR(F33*G33, 0) | K33: =IFERROR(I33*J33, 0) | N33: =IFERROR(L33*M33, 0) | Q33: =IFERROR(O33*P33, 0) | T33: =IFERROR(R33*S33, 0) | W33: =IFERROR(U33*V33, 0) | Z33: =IFERROR(X33*Y33, 0) | AC33: =IFERROR(AA33*AB33, 0) | AF33: =IFERROR(AD33*AE33, 0) | AI33: =IFERROR(AG33*AH33, 0) | AL33: =IFERROR(AJ33*AK33, 0) | AO33: =IFERROR(AM33*AN33, 0) | AR33: =IFERROR(AP33*AQ33, 0) | AU33: =IFERROR(AS33*AT33, 0) | AX33: =IFERROR(AV33*AW33, 0) | BA33: =IFERROR(AY33*AZ33, 0) | BD33: =IFERROR(BB33*BC33, 0) | BG33: =IFERROR(BE33*BF33, 0) | BJ33: =IFERROR(BH33*BI33, 0) | BM33: =IFERROR(BK33*BL33, 0) | BP33: =IFERROR(BN33*BO33, 0) | BS33: =IFERROR(BQ33*BR33, 0) | BV33: =IFERROR(BT33*BU33, 0) | BY33: =IFERROR(BW33*BX33, 0) | CB33: =IFERROR(BZ33*CA33, 0) | CE33: =IFERROR(CC33*CD33, 0) | CH33: =IFERROR(CF33*CG33, 0) | CK33: =IFERROR(CI33*CJ33, 0) | CN33: =IFERROR(CL33*CM33, 0) | CQ33: =IFERROR(CO33*CP33, 0) | CT33: =IFERROR(CR33*CS33, 0) | CU33: =IFERROR(SUM(F33,I33,L33,O33,R33,U33,X33,AA33,AD33,AG33,AJ33,AM33,AP33,AS33,AV33,AY33,BB33,BE33,BH33,BK33,BN33,BQ33,BT33,BW33,BZ33,CC33,CF33,CI33,CL33,CO33,CR33), 0) | CV33: =IFERROR(AVERAGE(G33,J33,M33,P33,S33,V33,Y33,AB33,AE33,AH33,AK33,AN33,AQ33,AT33,AW33,AZ33,BC33,BF33,BI33,BL33,BO33,BR33,BU33,BX33,CA33,CD33,CG33,CJ33,CM33,CP33,CS33), 0) | CW33: =CU33*CV33
A34: Higado | B34: Kg | E34: 0 | F34: 2 | G34: 22000 | H34: 44000 | K34: =IFERROR(I34*J34, 0) | N34: =IFERROR(L34*M34, 0) | Q34: =IFERROR(O34*P34, 0) | T34: =IFERROR(R34*S34, 0) | W34: =IFERROR(U34*V34, 0) | Z34: =IFERROR(X34*Y34, 0) | AC34: =IFERROR(AA34*AB34, 0) | AF34: =IFERROR(AD34*AE34, 0) | AI34: =IFERROR(AG34*AH34, 0) | AL34: =IFERROR(AJ34*AK34, 0) | AO34: =IFERROR(AM34*AN34, 0) | AR34: =IFERROR(AP34*AQ34, 0) | AU34: =IFERROR(AS34*AT34, 0) | AV34: 8.2 | AW34: 21500 | AX34: 176300 | BA34: =IFERROR(AY34*AZ34, 0) | BD34: =IFERROR(BB34*BC34, 0) | BG34: =IFERROR(BE34*BF34, 0) | BJ34: =IFERROR(BH34*BI34, 0) | BM34: =IFERROR(BK34*BL34, 0) | BP34: =IFERROR(BN34*BO34, 0) | BS34: =IFERROR(BQ34*BR34, 0) | BV34: =IFERROR(BT34*BU34, 0) | BY34: =IFERROR(BW34*BX34, 0) | CB34: =IFERROR(BZ34*CA34, 0) | CE34: =IFERROR(CC34*CD34, 0) | CH34: =IFERROR(CF34*CG34, 0) | CK34: =IFERROR(CI34*CJ34, 0) | CN34: =IFERROR(CL34*CM34, 0) | CQ34: =IFERROR(CO34*CP34, 0) | CT34: =IFERROR(CR34*CS34, 0) | CU34: =IFERROR(SUM(F34,I34,L34,O34,R34,U34,X34,AA34,AD34,AG34,AJ34,AM34,AP34,AS34,AV34,AY34,BB34,BE34,BH34,BK34,BN34,BQ34,BT34,BW34,BZ34,CC34,CF34,CI34,CL34,CO34,CR34), 0) | CV34: =IFERROR(AVERAGE(G34,J34,M34,P34,S34,V34,Y34,AB34,AE34,AH34,AK34,AN34,AQ34,AT34,AW34,AZ34,BC34,BF34,BI34,BL34,BO34,BR34,BU34,BX34,CA34,CD34,CG34,CJ34,CM34,CP34,CS34), 0) | CW34: =CU34*CV34
A35: Lengua de res | B35: Kg | E35: 0 | F35: 5.91 | G35: 23500 | H35: 138767.5 | K35: =IFERROR(I35*J35, 0) | N35: =IFERROR(L35*M35, 0) | O35: 5.43 | P35: 23500 | Q35: 127605 | T35: =IFERROR(R35*S35, 0) | W35: =IFERROR(U35*V35, 0) | X35: 42.6 | Y35: 22900 | Z35: 975540 | AC35: =IFERROR(AA35*AB35, 0) | AF35: =IFERROR(AD35*AE35, 0) | AI35: =IFERROR(AG35*AH35, 0) | AL35: =IFERROR(AJ35*AK35, 0) | AO35: =IFERROR(AM35*AN35, 0) | AR35: =IFERROR(AP35*AQ35, 0) | AU35: =IFERROR(AS35*AT35, 0) | AX35: =IFERROR(AV35*AW35, 0) | BA35: =IFERROR(AY35*AZ35, 0) | BB35: 40.1 | BC35: 22900 | BD35: 918290 | BG35: =IFERROR(BE35*BF35, 0) | BJ35: =IFERROR(BH35*BI35, 0) | BM35: =IFERROR(BK35*BL35, 0) | BP35: =IFERROR(BN35*BO35, 0) | BS35: =IFERROR(BQ35*BR35, 0) | BV35: =IFERROR(BT35*BU35, 0) | BY35: =IFERROR(BW35*BX35, 0) | CB35: =IFERROR(BZ35*CA35, 0) | CE35: =IFERROR(CC35*CD35, 0) | CH35: =IFERROR(CF35*CG35, 0) | CK35: =IFERROR(CI35*CJ35, 0) | CN35: =IFERROR(CL35*CM35, 0) | CQ35: =IFERROR(CO35*CP35, 0) | CT35: =IFERROR(CR35*CS35, 0) | CU35: =IFERROR(SUM(F35,I35,L35,O35,R35,U35,X35,AA35,AD35,AG35,AJ35,AM35,AP35,AS35,AV35,AY35,BB35,BE35,BH35,BK35,BN35,BQ35,BT35,BW35,BZ35,CC35,CF35,CI35,CL35,CO35,CR35), 0) | CV35: =IFERROR(AVERAGE(G35,J35,M35,P35,S35,V35,Y35,AB35,AE35,AH35,AK35,AN35,AQ35,AT35,AW35,AZ35,BC35,BF35,BI35,BL35,BO35,BR35,BU35,BX35,CA35,CD35,CG35,CJ35,CM35,CP35,CS35), 0) | CW35: =CU35*CV35
A36: Chorizo paisa | B36: Kg | E36: 0 | H36: =IFERROR(F36*G36, 0) | K36: =IFERROR(I36*J36, 0) | N36: =IFERROR(L36*M36, 0) | Q36: =IFERROR(O36*P36, 0) | T36: =IFERROR(R36*S36, 0) | W36: =IFERROR(U36*V36, 0) | Z36: =IFERROR(X36*Y36, 0) | AC36: =IFERROR(AA36*AB36, 0) | AF36: =IFERROR(AD36*AE36, 0) | AI36: =IFERROR(AG36*AH36, 0) | AL36: =IFERROR(AJ36*AK36, 0) | AO36: =IFERROR(AM36*AN36, 0) | AR36: =IFERROR(AP36*AQ36, 0) | AU36: =IFERROR(AS36*AT36, 0) | AX36: =IFERROR(AV36*AW36, 0) | BA36: =IFERROR(AY36*AZ36, 0) | BD36: =IFERROR(BB36*BC36, 0) | BG36: =IFERROR(BE36*BF36, 0) | BJ36: =IFERROR(BH36*BI36, 0) | BM36: =IFERROR(BK36*BL36, 0) | BP36: =IFERROR(BN36*BO36, 0) | BS36: =IFERROR(BQ36*BR36, 0) | BV36: =IFERROR(BT36*BU36, 0) | BY36: =IFERROR(BW36*BX36, 0) | CB36: =IFERROR(BZ36*CA36, 0) | CE36: =IFERROR(CC36*CD36, 0) | CH36: =IFERROR(CF36*CG36, 0) | CK36: =IFERROR(CI36*CJ36, 0) | CN36: =IFERROR(CL36*CM36, 0) | CQ36: =IFERROR(CO36*CP36, 0) | CT36: =IFERROR(CR36*CS36, 0) | CU36: =IFERROR(SUM(F36,I36,L36,O36,R36,U36,X36,AA36,AD36,AG36,AJ36,AM36,AP36,AS36,AV36,AY36,BB36,BE36,BH36,BK36,BN36,BQ36,BT36,BW36,BZ36,CC36,CF36,CI36,CL36,CO36,CR36), 0) | CV36: =IFERROR(AVERAGE(G36,J36,M36,P36,S36,V36,Y36,AB36,AE36,AH36,AK36,AN36,AQ36,AT36,AW36,AZ36,BC36,BF36,BI36,BL36,BO36,BR36,BU36,BX36,CA36,CD36,CG36,CJ36,CM36,CP36,CS36), 0) | CW36: =CU36*CV36
A37: Lomo de cerdo | B37: Kg | E37: 0 | F37: 13.2 | G37: 19800 | H37: 261360 | K37: =IFERROR(I37*J37, 0) | N37: =IFERROR(L37*M37, 0) | O37: 15.9 | P37: 19800 | Q37: 314820 | R37: 20.6 | S37: 19500 | T37: 401700 | U37: 10.57 | V37: 19800 | W37: 328986 | Z37: =IFERROR(X37*Y37, 0) | AC37: =IFERROR(AA37*AB37, 0) | AF37: =IFERROR(AD37*AE37, 0) | AI37: =IFERROR(AG37*AH37, 0) | AL37: =IFERROR(AJ37*AK37, 0) | AO37: =IFERROR(AM37*AN37, 0) | AR37: =IFERROR(AP37*AQ37, 0) | AU37: =IFERROR(AS37*AT37, 0) | AX37: =IFERROR(AV37*AW37, 0) | BA37: =IFERROR(AY37*AZ37, 0) | BD37: =IFERROR(BB37*BC37, 0) | BG37: =IFERROR(BE37*BF37, 0) | BJ37: =IFERROR(BH37*BI37, 0) | BM37: =IFERROR(BK37*BL37, 0) | BN37: 9.15 | BO37: 19500 | BP37: 178425 | BQ37: 18.31 | BR37: 19500 | BS37: 357045 | BV37: =IFERROR(BT37*BU37, 0) | BY37: =IFERROR(BW37*BX37, 0) | CB37: =IFERROR(BZ37*CA37, 0) | CE37: =IFERROR(CC37*CD37, 0) | CH37: =IFERROR(CF37*CG37, 0) | CI37: 9.15 | CJ37: 19500 | CK37: 178425 | CN37: =IFERROR(CL37*CM37, 0) | CQ37: =IFERROR(CO37*CP37, 0) | CT37: =IFERROR(CR37*CS37, 0) | CU37: =IFERROR(SUM(F37,I37,L37,O37,R37,U37,X37,AA37,AD37,AG37,AJ37,AM37,AP37,AS37,AV37,AY37,BB37,BE37,BH37,BK37,BN37,BQ37,BT37,BW37,BZ37,CC37,CF37,CI37,CL37,CO37,CR37), 0) | CV37: =IFERROR(AVERAGE(G37,J37,M37,P37,S37,V37,Y37,AB37,AE37,AH37,AK37,AN37,AQ37,AT37,AW37,AZ37,BC37,BF37,BI37,BL37,BO37,BR37,BU37,BX37,CA37,CD37,CG37,CJ37,CM37,CP37,CS37), 0) | CW37: =CU37*CV37
A38: Lomo viche | B38: Kg | E38: 0 | H38: =IFERROR(F38*G38, 0) | K38: =IFERROR(I38*J38, 0) | N38: =IFERROR(L38*M38, 0) | O38: 8.75 | P38: 45000 | Q38: 393750 | T38: =IFERROR(R38*S38, 0) | W38: =IFERROR(U38*V38, 0) | Z38: =IFERROR(X38*Y38, 0) | AC38: =IFERROR(AA38*AB38, 0) | AF38: =IFERROR(AD38*AE38, 0) | AI38: =IFERROR(AG38*AH38, 0) | AL38: =IFERROR(AJ38*AK38, 0) | AO38: =IFERROR(AM38*AN38, 0) | AP38: 5.75 | AQ38: 46000 | AR38: 264500 | AU38: =IFERROR(AS38*AT38, 0) | AX38: =IFERROR(AV38*AW38, 0) | BA38: =IFERROR(AY38*AZ38, 0) | BD38: =IFERROR(BB38*BC38, 0) | BG38: =IFERROR(BE38*BF38, 0) | BJ38: =IFERROR(BH38*BI38, 0) | BM38: =IFERROR(BK38*BL38, 0) | BP38: =IFERROR(BN38*BO38, 0) | BS38: =IFERROR(BQ38*BR38, 0) | BT38: 4.2 | BU38: 65900 | BV38: 276780 | BY38: =IFERROR(BW38*BX38, 0) | CB38: =IFERROR(BZ38*CA38, 0) | CE38: =IFERROR(CC38*CD38, 0) | CH38: =IFERROR(CF38*CG38, 0) | CK38: =IFERROR(CI38*CJ38, 0) | CN38: =IFERROR(CL38*CM38, 0) | CQ38: =IFERROR(CO38*CP38, 0) | CT38: =IFERROR(CR38*CS38, 0) | CU38: =IFERROR(SUM(F38,I38,L38,O38,R38,U38,X38,AA38,AD38,AG38,AJ38,AM38,AP38,AS38,AV38,AY38,BB38,BE38,BH38,BK38,BN38,BQ38,BT38,BW38,BZ38,CC38,CF38,CI38,CL38,CO38,CR38), 0) | CV38: =IFERROR(AVERAGE(G38,J38,M38,P38,S38,V38,Y38,AB38,AE38,AH38,AK38,AN38,AQ38,AT38,AW38,AZ38,BC38,BF38,BI38,BL38,BO38,BR38,BU38,BX38,CA38,CD38,CG38,CJ38,CM38,CP38,CS38), 0) | CW38: =CU38*CV38
A39: Marisco | B39: Kg | E39: 0 | H39: =IFERROR(F39*G39, 0) | K39: =IFERROR(I39*J39, 0) | N39: =IFERROR(L39*M39, 0) | Q39: =IFERROR(O39*P39, 0) | T39: =IFERROR(R39*S39, 0) | W39: =IFERROR(U39*V39, 0) | Z39: =IFERROR(X39*Y39, 0) | AC39: =IFERROR(AA39*AB39, 0) | AD39: 24 | AE39: 5000 | AF39: 120000 | AI39: =IFERROR(AG39*AH39, 0) | AL39: =IFERROR(AJ39*AK39, 0) | AO39: =IFERROR(AM39*AN39, 0) | AR39: =IFERROR(AP39*AQ39, 0) | AU39: =IFERROR(AS39*AT39, 0) | AX39: =IFERROR(AV39*AW39, 0) | BA39: =IFERROR(AY39*AZ39, 0) | BD39: =IFERROR(BB39*BC39, 0) | BG39: =IFERROR(BE39*BF39, 0) | BJ39: =IFERROR(BH39*BI39, 0) | BM39: =IFERROR(BK39*BL39, 0) | BP39: =IFERROR(BN39*BO39, 0) | BS39: =IFERROR(BQ39*BR39, 0) | BV39: =IFERROR(BT39*BU39, 0) | BY39: =IFERROR(BW39*BX39, 0) | CB39: =IFERROR(BZ39*CA39, 0) | CE39: =IFERROR(CC39*CD39, 0) | CH39: =IFERROR(CF39*CG39, 0) | CK39: =IFERROR(CI39*CJ39, 0) | CN39: =IFERROR(CL39*CM39, 0) | CQ39: =IFERROR(CO39*CP39, 0) | CT39: =IFERROR(CR39*CS39, 0) | CU39: =IFERROR(SUM(F39,I39,L39,O39,R39,U39,X39,AA39,AD39,AG39,AJ39,AM39,AP39,AS39,AV39,AY39,BB39,BE39,BH39,BK39,BN39,BQ39,BT39,BW39,BZ39,CC39,CF39,CI39,CL39,CO39,CR39), 0) | CV39: =IFERROR(AVERAGE(G39,J39,M39,P39,S39,V39,Y39,AB39,AE39,AH39,AK39,AN39,AQ39,AT39,AW39,AZ39,BC39,BF39,BI39,BL39,BO39,BR39,BU39,BX39,CA39,CD39,CG39,CJ39,CM39,CP39,CS39), 0) | CW39: =CU39*CV39
A40: Mix de verdura | B40: Paq | E40: 0 | H40: =IFERROR(F40*G40, 0) | I40: 10 | J40: 8487.4 | K40: 84874 | N40: =IFERROR(L40*M40, 0) | Q40: =IFERROR(O40*P40, 0) | T40: =IFERROR(R40*S40, 0) | W40: =IFERROR(U40*V40, 0) | Z40: =IFERROR(X40*Y40, 0) | AC40: =IFERROR(AA40*AB40, 0) | AF40: =IFERROR(AD40*AE40, 0) | AI40: =IFERROR(AG40*AH40, 0) | AL40: =IFERROR(AJ40*AK40, 0) | AO40: =IFERROR(AM40*AN40, 0) | AR40: =IFERROR(AP40*AQ40, 0) | AU40: =IFERROR(AS40*AT40, 0) | AX40: =IFERROR(AV40*AW40, 0) | BA40: =IFERROR(AY40*AZ40, 0) | BB40: 10 | BC40: 8487.4 | BD40: 84874 | BG40: =IFERROR(BE40*BF40, 0) | BJ40: =IFERROR(BH40*BI40, 0) | BM40: =IFERROR(BK40*BL40, 0) | BP40: =IFERROR(BN40*BO40, 0) | BS40: =IFERROR(BQ40*BR40, 0) | BV40: =IFERROR(BT40*BU40, 0) | BY40: =IFERROR(BW40*BX40, 0) | CB40: =IFERROR(BZ40*CA40, 0) | CE40: =IFERROR(CC40*CD40, 0) | CH40: =IFERROR(CF40*CG40, 0) | CK40: =IFERROR(CI40*CJ40, 0) | CN40: =IFERROR(CL40*CM40, 0) | CQ40: =IFERROR(CO40*CP40, 0) | CT40: =IFERROR(CR40*CS40, 0) | CU40: =IFERROR(SUM(F40,I40,L40,O40,R40,U40,X40,AA40,AD40,AG40,AJ40,AM40,AP40,AS40,AV40,AY40,BB40,BE40,BH40,BK40,BN40,BQ40,BT40,BW40,BZ40,CC40,CF40,CI40,CL40,CO40,CR40), 0) | CV40: =IFERROR(AVERAGE(G40,J40,M40,P40,S40,V40,Y40,AB40,AE40,AH40,AK40,AN40,AQ40,AT40,AW40,AZ40,BC40,BF40,BI40,BL40,BO40,BR40,BU40,BX40,CA40,CD40,CG40,CJ40,CM40,CP40,CS40), 0) | CW40: =CU40*CV40
...

Sheet Verduras
A1: Verduras | F1: 1 | I1: 2 | L1: 3 | O1: 4 | R1: 5 | U1: 6 | X1: 7 | AA1: 8 | AD1: 9 | AG1: 10 | AJ1: 11 | AM1: 12 | AP1: 13 | AS1: 14 | AV1: 15 | AY1: 16 | BB1: 17 | BE1: 18 | BH1: 19 | BK1: 20 | BN1: 21 | BQ1: 22 | BT1: 23 | BW1: 24 | BZ1: 25 | CC1: 26 | CF1: 27 | CI1: 28 | CL1: 29 | CO1: 30 | CR1: 31 | CU1: Total mes
A2: Producto | B2: Medida | C2: Inv -inicial | D2: Valor | E2: Total | F2: Cantid | G2: Costo unit | H2: Vr. compra | I2: Cantid | J2: Costo unit | K2: Vr. compra | L2: Cantid | M2: Costo unit | N2: Vr. compra | O2: Cantid | P2: Costo unit | Q2: Vr. compra | R2: Cantid | S2: Costo | T2: Vr. compra | U2: Cantid | V2: Costo unit | W2: Vr. compra | X2: Cantid | Y2: Costo unit | Z2: Vr. compra | AA2: Cantid | AB2: Costo unit | AC2: Vr. compra | AD2: Cantid | AE2: Costo unit | AF2: Vr. compra | AG2: Cantid | AH2: Costo unit | AI2: Vr. compra | AJ2: Cantid | AK2: Costo unit | AL2: Vr. compra | AM2: Cantid | AN2: Costo unit | AO2: Vr. compra | AP2: Cantid | AQ2: Costo | AR2: Vr. compra | AS2: Cantid | AT2: Costo unit | AU2: Vr. compra | AV2: Cantid | AW2: Costo unit | AX2: Vr. compra | AY2: Cantid | AZ2: Costo unit | BA2: Vr. compra | BB2: Cantid | BC2: Costo unit | BD2: Vr. compra | BE2: Cantid | BF2: Costo unit | BG2: Vr. compra | BH2: Cantid | BI2: Costo unit | BJ2: Vr. compra | BK2: Cantid | BL2: Costo unit | BM2: Vr. compra | BN2: Cantid | BO2: Costo | BP2: Vr. compra | BQ2: Cantid | BR2: Costo unit | BS2: Vr. compra | BT2: Cantid | BU2: Costo unit | BV2: Vr. compra | BW2: Cantid | BX2: Costo unit | BY2: Vr. compra | BZ2: Cantid | CA2: Costo unit | CB2: Vr. compra | CC2: Cantid | CD2: Costo unit | CE2: Vr. compra | CF2: Cantid | CG2: Costo unit | CH2: Vr. compra | CI2: Cantid | CJ2: Costo unit | CK2: Vr. compra | CL2: Cantid | CM2: Costo | CN2: Vr. compra | CO2: Cantid | CP2: Costo unit | CQ2: Vr. compra | CR2: Cantid | CS2: Costo unit | CT2: Vr. compra | CU2: Cantid | CV2: Costo unit | CW2: Vr. compra
A3: Zapayo | B3: Kg | H3: =IFERROR(F3*G3, 0) | K3: =IFERROR(I3*J3, 0) | N3: =IFERROR(L3*M3, 0) | Q3: =IFERROR(O3*P3, 0) | T3: =IFERROR(R3*S3, 0) | W3: =IFERROR(U3*V3, 0) | Z3: =IFERROR(X3*Y3, 0) | AC3: =IFERROR(AA3*AB3, 0) | AF3: =IFERROR(AD3*AE3, 0) | AI3: =IFERROR(AG3*AH3, 0) | AL3: =IFERROR(AJ3*AK3, 0) | AO3: =IFERROR(AM3*AN3, 0) | AR3: =IFERROR(AP3*AQ3, 0) | AU3: =IFERROR(AS3*AT3, 0) | AX3: =IFERROR(AV3*AW3, 0) | BA3: =IFERROR(AY3*AZ3, 0) | BD3: =IFERROR(BB3*BC3, 0) | BG3: =IFERROR(BE3*BF3, 0) | BJ3: =IFERROR(BH3*BI3, 0) | BM3: =IFERROR(BK3*BL3, 0) | BP3: =IFERROR(BN3*BO3, 0) | BS3: =IFERROR(BQ3*BR3, 0) | BV3: =IFERROR(BT3*BU3, 0) | BY3: =IFERROR(BW3*BX3, 0) | CB3: =IFERROR(BZ3*CA3, 0) | CE3: =IFERROR(CC3*CD3, 0) | CH3: =IFERROR(CF3*CG3, 0) | CK3: =IFERROR(CI3*CJ3, 0) | CN3: =IFERROR(CL3*CM3, 0) | CQ3: =IFERROR(CO3*CP3, 0) | CT3: =IFERROR(CR3*CS3, 0) | CU3: =IFERROR(SUM(F3,I3,L3,O3,R3,U3,X3,AA3,AD3,AG3,AJ3,AM3,AP3,AS3,AV3,AY3,BB3,BE3,BH3,BK3,BN3,BQ3,BT3,BW3,BZ3,CC3,CF3,CI3,CL3,CO3,CR3), 0) | CV3: =IFERROR(AVERAGE(G3,J3,M3,P3,S3,V3,Y3,AB3,AE3,AH3,AK3,AN3,AQ3,AT3,AW3,AZ3,BC3,BF3,BI3,BL3,BO3,BR3,BU3,BX3,CA3,CD3,CG3,CJ3,CM3,CP3,CS3), 0) | CW3: =CU3*CV3
A4: Zanahoria | B4: Kg | H4: =IFERROR(F4*G4, 0) | K4: =IFERROR(I4*J4, 0) | N4: =IFERROR(L4*M4, 0) | Q4: =IFERROR(O4*P4, 0) | T4: =IFERROR(R4*S4, 0) | W4: =IFERROR(U4*V4, 0) | Z4: =IFERROR(X4*Y4, 0) | AC4: =IFERROR(AA4*AB4, 0) | AF4: =IFERROR(AD4*AE4, 0) | AI4: =IFERROR(AG4*AH4, 0) | AL4: =IFERROR(AJ4*AK4, 0) | AO4: =IFERROR(AM4*AN4, 0) | AP4: 16.5 | AQ4: 2800 | AR4: 44460 | AS4: 9.1 | AT4: 2000 | AU4: 18200 | AX4: =IFERROR(AV4*AW4, 0) | BA4: =IFERROR(AY4*AZ4, 0) | BD4: =IFERROR(BB4*BC4, 0) | BG4: =IFERROR(BE4*BF4, 0) | BJ4: =IFERROR(BH4*BI4, 0) | BM4: =IFERROR(BK4*BL4, 0) | BN4: 15.2 | BO4: 2000 | BP4: 36700 | BS4: =IFERROR(BQ4*BR4, 0) | BV4: =IFERROR(BT4*BU4, 0) | BY4: =IFERROR(BW4*BX4, 0) | CB4: =IFERROR(BZ4*CA4, 0) | CE4: =IFERROR(CC4*CD4, 0) | CH4: =IFERROR(CF4*CG4, 0) | CK4: =IFERROR(CI4*CJ4, 0) | CN4: =IFERROR(CL4*CM4, 0) | CQ4: =IFERROR(CO4*CP4, 0) | CT4: =IFERROR(CR4*CS4, 0) | CU4: =IFERROR(SUM(F4,I4,L4,O4,R4,U4,X4,AA4,AD4,AG4,AJ4,AM4,AP4,AS4,AV4,AY4,BB4,BE4,BH4,BK4,BN4,BQ4,BT4,BW4,BZ4,CC4,CF4,CI4,CL4,CO4,CR4), 0) | CV4: =IFERROR(AVERAGE(G4,J4,M4,P4,S4,V4,Y4,AB4,AE4,AH4,AK4,AN4,AQ4,AT4,AW4,AZ4,BC4,BF4,BI4,BL4,BO4,BR4,BU4,BX4,CA4,CD4,CG4,CJ4,CM4,CP4,CS4), 0) | CW4: =CU4*CV4
A5: Yuca | B5: Kg | H5: =IFERROR(F5*G5, 0) | K5: =IFERROR(I5*J5, 0) | N5: =IFERROR(L5*M5, 0) | Q5: =IFERROR(O5*P5, 0) | T5: =IFERROR(R5*S5, 0) | W5: =IFERROR(U5*V5, 0) | Z5: =IFERROR(X5*Y5, 0) | AC5: =IFERROR(AA5*AB5, 0) | AF5: =IFERROR(AD5*AE5, 0) | AI5: =IFERROR(AG5*AH5, 0) | AL5: =IFERROR(AJ5*AK5, 0) | AO5: =IFERROR(AM5*AN5, 0) | AR5: =IFERROR(AP5*AQ5, 0) | AU5: =IFERROR(AS5*AT5, 0) | AX5: =IFERROR(AV5*AW5, 0) | BA5: =IFERROR(AY5*AZ5, 0) | BD5: =IFERROR(BB5*BC5, 0) | BG5: =IFERROR(BE5*BF5, 0) | BJ5: =IFERROR(BH5*BI5, 0) | BM5: =IFERROR(BK5*BL5, 0) | BP5: =IFERROR(BN5*BO5, 0) | BS5: =IFERROR(BQ5*BR5, 0) | BV5: =IFERROR(BT5*BU5, 0) | BY5: =IFERROR(BW5*BX5, 0) | CB5: =IFERROR(BZ5*CA5, 0) | CE5: =IFERROR(CC5*CD5, 0) | CH5: =IFERROR(CF5*CG5, 0) | CK5: =IFERROR(CI5*CJ5, 0) | CN5: =IFERROR(CL5*CM5, 0) | CQ5: =IFERROR(CO5*CP5, 0) | CT5: =IFERROR(CR5*CS5, 0) | CU5: =IFERROR(SUM(F5,I5,L5,O5,R5,U5,X5,AA5,AD5,AG5,AJ5,AM5,AP5,AS5,AV5,AY5,BB5,BE5,BH5,BK5,BN5,BQ5,BT5,BW5,BZ5,CC5,CF5,CI5,CL5,CO5,CR5), 0) | CV5: =IFERROR(AVERAGE(G5,J5,M5,P5,S5,V5,Y5,AB5,AE5,AH5,AK5,AN5,AQ5,AT5,AW5,AZ5,BC5,BF5,BI5,BL5,BO5,BR5,BU5,BX5,CA5,CD5,CG5,CJ5,CM5,CP5,CS5), 0) | CW5: =CU5*CV5
A6: Uva | B6: Kg | H6: =IFERROR(F6*G6, 0) | K6: =IFERROR(I6*J6, 0) | N6: =IFERROR(L6*M6, 0) | Q6: =IFERROR(O6*P6, 0) | T6: =IFERROR(R6*S6, 0) | W6: =IFERROR(U6*V6, 0) | Z6: =IFERROR(X6*Y6, 0) | AC6: =IFERROR(AA6*AB6, 0) | AF6: =IFERROR(AD6*AE6, 0) | AI6: =IFERROR(AG6*AH6, 0) | AL6: =IFERROR(AJ6*AK6, 0) | AO6: =IFERROR(AM6*AN6, 0) | AR6: =IFERROR(AP6*AQ6, 0) | AU6: =IFERROR(AS6*AT6, 0) | AX6: =IFERROR(AV6*AW6, 0) | BA6: =IFERROR(AY6*AZ6, 0) | BD6: =IFERROR(BB6*BC6, 0) | BG6: =IFERROR(BE6*BF6, 0) | BJ6: =IFERROR(BH6*BI6, 0) | BM6: =IFERROR(BK6*BL6, 0) | BP6: =IFERROR(BN6*BO6, 0) | BS6: =IFERROR(BQ6*BR6, 0) | BV6: =IFERROR(BT6*BU6, 0) | BY6: =IFERROR(BW6*BX6, 0) | CB6: =IFERROR(BZ6*CA6, 0) | CE6: =IFERROR(CC6*CD6, 0) | CH6: =IFERROR(CF6*CG6, 0) | CK6: =IFERROR(CI6*CJ6, 0) | CN6: =IFERROR(CL6*CM6, 0) | CQ6: =IFERROR(CO6*CP6, 0) | CT6: =IFERROR(CR6*CS6, 0) | CU6: =IFERROR(SUM(F6,I6,L6,O6,R6,U6,X6,AA6,AD6,AG6,AJ6,AM6,AP6,AS6,AV6,AY6,BB6,BE6,BH6,BK6,BN6,BQ6,BT6,BW6,BZ6,CC6,CF6,CI6,CL6,CO6,CR6), 0) | CV6: =IFERROR(AVERAGE(G6,J6,M6,P6,S6,V6,Y6,AB6,AE6,AH6,AK6,AN6,AQ6,AT6,AW6,AZ6,BC6,BF6,BI6,BL6,BO6,BR6,BU6,BX6,CA6,CD6,CG6,CJ6,CM6,CP6,CS6), 0) | CW6: =CU6*CV6
