Workbook

Sheet Dashboard
B2: RESTAURANTE CHOCLOS Y ASADOS LA FINCA
B3: DASHBOARD GERENCIAL DE COSTOS Y GASTOS - INFORME MENSUAL Y DIARIO AGOSTO 2026
B5: TOTAL COMPRAS Y EGRESOS | E5: TOTAL COSTOS DIRECTOS | H5: TOTAL GASTOS OPERACIONALES | K5: PROMEDIO DIARIO TOTAL
B6: =E59 | E6: =C59 | H6: =D59 | K6: =E60
B7: 100% Consolidado del Mes | E7: =TEXT(C59/E59,"0.0%") & " del Total (Materia Prima/Insumos)" | H7: =TEXT(D59/E59,"0.0%") & " del Total (Servicios/Nómina)" | K7: ="Costo Prom: " & TEXT(C60,"$#,##0") & " | Gasto Prom: " & TEXT(D60,"$#,##0")
B9: 1. CLASIFICACIÓN GERENCIAL: COSTOS DIRECTOS VS GASTOS OPERACIONALES
B10: Tipo | C10: Naturaleza / Componentes | D10: Registros | E10: Total Mes ($) | F10: % Total | G10: Promedio Diario
B11: Costos Directos (COGS) | C11: Materia Prima (Carnes, Verduras, Grano, Bebidas, Desechables) | D11: =COUNTIF('Detalle Compras Agosto 2026'!$B:$B,"<>Servicios")-1 | E11: =C59 | F11: =E11/$E$13 | G11: =E11/COUNTIF($E$28:$E$58,">0")
B12: Gastos Operacionales | C12: Servicios Públicos, Nómina, Turnos, Mantenimiento, Taxis | D12: =COUNTIF('Detalle Compras Agosto 2026'!$B:$B,"Servicios") | E12: =D59 | F12: =E12/$E$13 | G12: =E12/COUNTIF($E$28:$E$58,">0")
B13: TOTAL CONSOLIDADO MES | C13: 100% Egresos Registrados en Agosto | D13: =SUM(D11:D12) | E13: =SUM(E11:E12) | F13: =SUM(F11:F12) | G13: =SUM(G11:G12)
B15: 2. ESTRUCTURA DE COSTOS Y GASTOS POR CATEGORÍA
B16: Categoría | C16: Tipo Contable | D16: N° Compras | E16: Total Mes ($) | F16: % Total | G16: Promedio Diario
B17: Carnes | C17: Costo Directo | D17: =COUNTIF('Detalle Compras Agosto 2026'!$B:$B,"Carnes") | E17: =H59 | F17: =E17/$E$23 | G17: =E17/COUNTIF($E$28:$E$58,">0")
B18: Servicios | C18: Gasto Operacional | D18: =COUNTIF('Detalle Compras Agosto 2026'!$B:$B,"Servicios") | E18: =M59 | F18: =E18/$E$23 | G18: =E18/COUNTIF($E$28:$E$58,">0")
B19: Desechables | C19: Costo Directo | D19: =COUNTIF('Detalle Compras Agosto 2026'!$B:$B,"Desechables") | E19: =L59 | F19: =E19/$E$23 | G19: =E19/COUNTIF($E$28:$E$58,">0")
B20: Verduras | C20: Costo Directo | D20: =COUNTIF('Detalle Compras Agosto 2026'!$B:$B,"Verduras") | E20: =I59 | F20: =E20/$E$23 | G20: =E20/COUNTIF($E$28:$E$58,">0")
B21: Grano | C21: Costo Directo | D21: =COUNTIF('Detalle Compras Agosto 2026'!$B:$B,"Grano") | E21: =J59 | F21: =E21/$E$23 | G21: =E21/COUNTIF($E$28:$E$58,">0")
B22: Bebidas | C22: Costo Directo | D22: =COUNTIF('Detalle Compras Agosto 2026'!$B:$B,"Bebidas") | E22: =K59 | F22: =E22/$E$23 | G22: =E22/COUNTIF($E$28:$E$58,">0")
B23: TOTAL CATEGORÍAS | C23: Consolidado General | D23: =SUM(D17:D22) | E23: =SUM(E17:E22) | F23: =SUM(F17:F22) | G23: =SUM(G17:G22)
B26: 3. TOTALIZACIÓN DIARIA: COSTOS Y GASTOS DÍA A DÍA (AGOSTO 2026)
B27: Día | C27: Costos ($) | D27: Gastos ($) | E27: Total Día ($) | F27: % Costo | G27: % Gasto | H27: Carnes ($) | I27: Verduras ($) | J27: Grano ($) | K27: Bebidas ($) | L27: Desechables ($) | M27: Servicios ($) | N27: N° Compras
B28: 1 | C28: =SUMIFS('Detalle Compras Agosto 2026'!$G:$G, 'Detalle Compras Agosto 2026'!$A:$A, B28, 'Detalle Compras Agosto 2026'!$B:$B, "<>Servicios") | D28: =SUMIFS('Detalle Compras Agosto 2026'!$G:$G, 'Detalle Compras Agosto 2026'!$A:$A, B28, 'Detalle Compras Agosto 2026'!$B:$B, "Servicios") | E28: =C28+D28 | F28: =IF(E28>0, C28/E28, 0) | G28: =IF(E28>0, D28/E28, 0) | H28: =SUMIFS('Detalle Compras Agosto 2026'!$G:$G, 'Detalle Compras Agosto 2026'!$A:$A, B28, 'Detalle Compras Agosto 2026'!$B:$B, "Carnes") | I28: =SUMIFS('Detalle Compras Agosto 2026'!$G:$G, 'Detalle Compras Agosto 2026'!$A:$A, B28, 'Detalle Compras Agosto 2026'!$B:$B, "Verduras") | J28: =SUMIFS('Detalle Compras Agosto 2026'!$G:$G, 'Detalle Compras Agosto 2026'!$A:$A, B28, 'Detalle Compras Agosto 2026'!$B:$B, "Grano") | K28: =SUMIFS('Detalle Compras Agosto 2026'!$G:$G, 'Detalle Compras Agosto 2026'!$A:$A, B28, 'Detalle Compras Agosto 2026'!$B:$B, "Bebidas") | L28: =SUMIFS('Detalle Compras Agosto 2026'!$G:$G, 'Detalle Compras Agosto 2026'!$A:$A, B28, 'Detalle Compras Agosto 2026'!$B:$B, "Desechables") | M28: =SUMIFS('Detalle Compras Agosto 2026'!$G:$G, 'Detalle Compras Agosto 2026'!$A:$A, B28, 'Detalle Compras Agosto 2026'!$B:$B, "Servicios") | N28: =COUNTIF('Detalle Compras Agosto 2026'!$A:$A, B28)
B29: 2 | C29: =SUMIFS('Detalle Compras Agosto 2026'!$G:$G, 'Detalle Compras Agosto 2026'!$A:$A, B29, 'Detalle Compras Agosto 2026'!$B:$B, "<>Servicios") | D29: =SUMIFS('Detalle Compras Agosto 2026'!$G:$G, 'Detalle Compras Agosto 2026'!$A:$A, B29, 'Detalle Compras Agosto 2026'!$B:$B, "Servicios") | E29: =C29+D29 | F29: =IF(E29>0, C29/E29, 0) | G29: =IF(E29>0, D29/E29, 0) | H29: =SUMIFS('Detalle Compras Agosto 2026'!$G:$G, 'Detalle Compras Agosto 2026'!$A:$A, B29, 'Detalle Compras Agosto 2026'!$B:$B, "Carnes") | I29: =SUMIFS('Detalle Compras Agosto 2026'!$G:$G, 'Detalle Compras Agosto 2026'!$A:$A, B29, 'Detalle Compras Agosto 2026'!$B:$B, "Verduras") | J29: =SUMIFS('Detalle Compras Agosto 2026'!$G:$G, 'Detalle Compras Agosto 2026'!$A:$A, B29, 'Detalle Compras Agosto 2026'!$B:$B, "Grano") | K29: =SUMIFS('Detalle Compras Agosto 2026'!$G:$G, 'Detalle Compras Agosto 2026'!$A:$A, B29, 'Detalle Compras Agosto 2026'!$B:$B, "Bebidas") | L29: =SUMIFS('Detalle Compras Agosto 2026'!$G:$G, 'Detalle Compras Agosto 2026'!$A:$A, B29, 'Detalle Compras Agosto 2026'!$B:$B, "Desechables") | M29: =SUMIFS('Detalle Compras Agosto 2026'!$G:$G, 'Detalle Compras Agosto 2026'!$A:$A, B29, 'Detalle Compras Agosto 2026'!$B:$B, "Servicios") | N29: =COUNTIF('Detalle Compras Agosto 2026'!$A:$A, B29)
B30: 3 | C30: =SUMIFS('Detalle Compras Agosto 2026'!$G:$G, 'Detalle Compras Agosto 2026'!$A:$A, B30, 'Detalle Compras Agosto 2026'!$B:$B, "<>Servicios") | D30: =SUMIFS('Detalle Compras Agosto 2026'!$G:$G, 'Detalle Compras Agosto 2026'!$A:$A, B30, 'Detalle Compras Agosto 2026'!$B:$B, "Servicios") | E30: =C30+D30 | F30: =IF(E30>0, C30/E30, 0) | G30: =IF(E30>0, D30/E30, 0) | H30: =SUMIFS('Detalle Compras Agosto 2026'!$G:$G, 'Detalle Compras Agosto 2026'!$A:$A, B30, 'Detalle Compras Agosto 2026'!$B:$B, "Carnes") | I30: =SUMIFS('Detalle Compras Agosto 2026'!$G:$G, 'Detalle Compras Agosto 2026'!$A:$A, B30, 'Detalle Compras Agosto 2026'!$B:$B, "Verduras") | J30: =SUMIFS('Detalle Compras Agosto 2026'!$G:$G, 'Detalle Compras Agosto 2026'!$A:$A, B30, 'Detalle Compras Agosto 2026'!$B:$B, "Grano") | K30: =SUMIFS('Detalle Compras Agosto 2026'!$G:$G, 'Detalle Compras Agosto 2026'!$A:$A, B30, 'Detalle Compras Agosto 2026'!$B:$B, "Bebidas") | L30: =SUMIFS('Detalle Compras Agosto 2026'!$G:$G, 'Detalle Compras Agosto 2026'!$A:$A, B30, 'Detalle Compras Agosto 2026'!$B:$B, "Desechables") | M30: =SUMIFS('Detalle Compras Agosto 2026'!$G:$G, 'Detalle Compras Agosto 2026'!$A:$A, B30, 'Detalle Compras Agosto 2026'!$B:$B, "Servicios") | N30: =COUNTIF('Detalle Compras Agosto 2026'!$A:$A, B30)
B31: 4 | C31: =SUMIFS('Detalle Compras Agosto 2026'!$G:$G, 'Detalle Compras Agosto 2026'!$A:$A, B31, 'Detalle Compras Agosto 2026'!$B:$B, "<>Servicios") | D31: =SUMIFS('Detalle Compras Agosto 2026'!$G:$G, 'Detalle Compras Agosto 2026'!$A:$A, B31, 'Detalle Compras Agosto 2026'!$B:$B, "Servicios") | E31: =C31+D31 | F31: =IF(E31>0, C31/E31, 0) | G31: =IF(E31>0, D31/E31, 0) | H31: =SUMIFS('Detalle Compras Agosto 2026'!$G:$G, 'Detalle Compras Agosto 2026'!$A:$A, B31, 'Detalle Compras Agosto 2026'!$B:$B, "Carnes") | I31: =SUMIFS('Detalle Compras Agosto 2026'!$G:$G, 'Detalle Compras Agosto 2026'!$A:$A, B31, 'Detalle Compras Agosto 2026'!$B:$B, "Verduras") | J31: =SUMIFS('Detalle Compras Agosto 2026'!$G:$G, 'Detalle Compras Agosto 2026'!$A:$A, B31, 'Detalle Compras Agosto 2026'!$B:$B, "Grano") | K31: =SUMIFS('Detalle Compras Agosto 2026'!$G:$G, 'Detalle Compras Agosto 2026'!$A:$A, B31, 'Detalle Compras Agosto 2026'!$B:$B, "Bebidas") | L31: =SUMIFS('Detalle Compras Agosto 2026'!$G:$G, 'Detalle Compras Agosto 2026'!$A:$A, B31, 'Detalle Compras Agosto 2026'!$B:$B, "Desechables") | M31: =SUMIFS('Detalle Compras Agosto 2026'!$G:$G, 'Detalle Compras Agosto 2026'!$A:$A, B31, 'Detalle Compras Agosto 2026'!$B:$B, "Servicios") | N31: =COUNTIF('Detalle Compras Agosto 2026'!$A:$A, B31)
B32: 5 | C32: =SUMIFS('Detalle Compras Agosto 2026'!$G:$G, 'Detalle Compras Agosto 2026'!$A:$A, B32, 'Detalle Compras Agosto 2026'!$B:$B, "<>Servicios") | D32: =SUMIFS('Detalle Compras Agosto 2026'!$G:$G, 'Detalle Compras Agosto 2026'!$A:$A, B32, 'Detalle Compras Agosto 2026'!$B:$B, "Servicios") | E32: =C32+D32 | F32: =IF(E32>0, C32/E32, 0) | G32: =IF(E32>0, D32/E32, 0) | H32: =SUMIFS('Detalle Compras Agosto 2026'!$G:$G, 'Detalle Compras Agosto 2026'!$A:$A, B32, 'Detalle Compras Agosto 2026'!$B:$B, "Carnes") | I32: =SUMIFS('Detalle Compras Agosto 2026'!$G:$G, 'Detalle Compras Agosto 2026'!$A:$A, B32, 'Detalle Compras Agosto 2026'!$B:$B, "Verduras") | J32: =SUMIFS('Detalle Compras Agosto 2026'!$G:$G, 'Detalle Compras Agosto 2026'!$A:$A, B32, 'Detalle Compras Agosto 2026'!$B:$B, "Grano") | K32: =SUMIFS('Detalle Compras Agosto 2026'!$G:$G, 'Detalle Compras Agosto 2026'!$A:$A, B32, 'Detalle Compras Agosto 2026'!$B:$B, "Bebidas") | L32: =SUMIFS('Detalle Compras Agosto 2026'!$G:$G, 'Detalle Compras Agosto 2026'!$A:$A, B32, 'Detalle Compras Agosto 2026'!$B:$B, "Desechables") | M32: =SUMIFS('Detalle Compras Agosto 2026'!$G:$G, 'Detalle Compras Agosto 2026'!$A:$A, B32, 'Detalle Compras Agosto 2026'!$B:$B, "Servicios") | N32: =COUNTIF('Detalle Compras Agosto 2026'!$A:$A, B32)
B33: 6 | C33: =SUMIFS('Detalle Compras Agosto 2026'!$G:$G, 'Detalle Compras Agosto 2026'!$A:$A, B33, 'Detalle Compras Agosto 2026'!$B:$B, "<>Servicios") | D33: =SUMIFS('Detalle Compras Agosto 2026'!$G:$G, 'Detalle Compras Agosto 2026'!$A:$A, B33, 'Detalle Compras Agosto 2026'!$B:$B, "Servicios") | E33: =C33+D33 | F33: =IF(E33>0, C33/E33, 0) | G33: =IF(E33>0, D33/E33, 0) | H33: =SUMIFS('Detalle Compras Agosto 2026'!$G:$G, 'Detalle Compras Agosto 2026'!$A:$A, B33, 'Detalle Compras Agosto 2026'!$B:$B, "Carnes") | I33: =SUMIFS('Detalle Compras Agosto 2026'!$G:$G, 'Detalle Compras Agosto 2026'!$A:$A, B33, 'Detalle Compras Agosto 2026'!$B:$B, "Verduras") | J33: =SUMIFS('Detalle Compras Agosto 2026'!$G:$G, 'Detalle Compras Agosto 2026'!$A:$A, B33, 'Detalle Compras Agosto 2026'!$B:$B, "Grano") | K33: =SUMIFS('Detalle Compras Agosto 2026'!$G:$G, 'Detalle Compras Agosto 2026'!$A:$A, B33, 'Detalle Compras Agosto 2026'!$B:$B, "Bebidas") | L33: =SUMIFS('Detalle Compras Agosto 2026'!$G:$G, 'Detalle Compras Agosto 2026'!$A:$A, B33, 'Detalle Compras Agosto 2026'!$B:$B, "Desechables") | M33: =SUMIFS('Detalle Compras Agosto 2026'!$G:$G, 'Detalle Compras Agosto 2026'!$A:$A, B33, 'Detalle Compras Agosto 2026'!$B:$B, "Servicios") | N33: =COUNTIF('Detalle Compras Agosto 2026'!$A:$A, B33)
B34: 7 | C34: =SUMIFS('Detalle Compras Agosto 2026'!$G:$G, 'Detalle Compras Agosto 2026'!$A:$A, B34, 'Detalle Compras Agosto 2026'!$B:$B, "<>Servicios") | D34: =SUMIFS('Detalle Compras Agosto 2026'!$G:$G, 'Detalle Compras Agosto 2026'!$A:$A, B34, 'Detalle Compras Agosto 2026'!$B:$B, "Servicios") | E34: =C34+D34 | F34: =IF(E34>0, C34/E34, 0) | G34: =IF(E34>0, D34/E34, 0) | H34: =SUMIFS('Detalle Compras Agosto 2026'!$G:$G, 'Detalle Compras Agosto 2026'!$A:$A, B34, 'Detalle Compras Agosto 2026'!$B:$B, "Carnes") | I34: =SUMIFS('Detalle Compras Agosto 2026'!$G:$G, 'Detalle Compras Agosto 2026'!$A:$A, B34, 'Detalle Compras Agosto 2026'!$B:$B, "Verduras") | J34: =SUMIFS('Detalle Compras Agosto 2026'!$G:$G, 'Detalle Compras Agosto 2026'!$A:$A, B34, 'Detalle Compras Agosto 2026'!$B:$B, "Grano") | K34: =SUMIFS('Detalle Compras Agosto 2026'!$G:$G, 'Detalle Compras Agosto 2026'!$A:$A, B34, 'Detalle Compras Agosto 2026'!$B:$B, "Bebidas") | L34: =SUMIFS('Detalle Compras Agosto 2026'!$G:$G, 'Detalle Compras Agosto 2026'!$A:$A, B34, 'Detalle Compras Agosto 2026'!$B:$B, "Desechables") | M34: =SUMIFS('Detalle Compras Agosto 2026'!$G:$G, 'Detalle Compras Agosto 2026'!$A:$A, B34, 'Detalle Compras Agosto 2026'!$B:$B, "Servicios") | N34: =COUNTIF('Detalle Compras Agosto 2026'!$A:$A, B34)
B35: 8 | C35: =SUMIFS('Detalle Compras Agosto 2026'!$G:$G, 'Detalle Compras Agosto 2026'!$A:$A, B35, 'Detalle Compras Agosto 2026'!$B:$B, "<>Servicios") | D35: =SUMIFS('Detalle Compras Agosto 2026'!$G:$G, 'Detalle Compras Agosto 2026'!$A:$A, B35, 'Detalle Compras Agosto 2026'!$B:$B, "Servicios") | E35: =C35+D35 | F35: =IF(E35>0, C35/E35, 0) | G35: =IF(E35>0, D35/E35, 0) | H35: =SUMIFS('Detalle Compras Agosto 2026'!$G:$G, 'Detalle Compras Agosto 2026'!$A:$A, B35, 'Detalle Compras Agosto 2026'!$B:$B, "Carnes") | I35: =SUMIFS('Detalle Compras Agosto 2026'!$G:$G, 'Detalle Compras Agosto 2026'!$A:$A, B35, 'Detalle Compras Agosto 2026'!$B:$B, "Verduras") | J35: =SUMIFS('Detalle Compras Agosto 2026'!$G:$G, 'Detalle Compras Agosto 2026'!$A:$A, B35, 'Detalle Compras Agosto 2026'!$B:$B, "Grano") | K35: =SUMIFS('Detalle Compras Agosto 2026'!$G:$G, 'Detalle Compras Agosto 2026'!$A:$A, B35, 'Detalle Compras Agosto 2026'!$B:$B, "Bebidas") | L35: =SUMIFS('Detalle Compras Agosto 2026'!$G:$G, 'Detalle Compras Agosto 2026'!$A:$A, B35, 'Detalle Compras Agosto 2026'!$B:$B, "Desechables") | M35: =SUMIFS('Detalle Compras Agosto 2026'!$G:$G, 'Detalle Compras Agosto 2026'!$A:$A, B35, 'Detalle Compras Agosto 2026'!$B:$B, "Servicios") | N35: =COUNTIF('Detalle Compras Agosto 2026'!$A:$A, B35)
B36: 9 | C36: =SUMIFS('Detalle Compras Agosto 2026'!$G:$G, 'Detalle Compras Agosto 2026'!$A:$A, B36, 'Detalle Compras Agosto 2026'!$B:$B, "<>Servicios") | D36: =SUMIFS('Detalle Compras Agosto 2026'!$G:$G, 'Detalle Compras Agosto 2026'!$A:$A, B36, 'Detalle Compras Agosto 2026'!$B:$B, "Servicios") | E36: =C36+D36 | F36: =IF(E36>0, C36/E36, 0) | G36: =IF(E36>0, D36/E36, 0) | H36: =SUMIFS('Detalle Compras Agosto 2026'!$G:$G, 'Detalle Compras Agosto 2026'!$A:$A, B36, 'Detalle Compras Agosto 2026'!$B:$B, "Carnes") | I36: =SUMIFS('Detalle Compras Agosto 2026'!$G:$G, 'Detalle Compras Agosto 2026'!$A:$A, B36, 'Detalle Compras Agosto 2026'!$B:$B, "Verduras") | J36: =SUMIFS('Detalle Compras Agosto 2026'!$G:$G, 'Detalle Compras Agosto 2026'!$A:$A, B36, 'Detalle Compras Agosto 2026'!$B:$B, "Grano") | K36: =SUMIFS('Detalle Compras Agosto 2026'!$G:$G, 'Detalle Compras Agosto 2026'!$A:$A, B36, 'Detalle Compras Agosto 2026'!$B:$B, "Bebidas") | L36: =SUMIFS('Detalle Compras Agosto 2026'!$G:$G, 'Detalle Compras Agosto 2026'!$A:$A, B36, 'Detalle Compras Agosto 2026'!$B:$B, "Desechables") | M36: =SUMIFS('Detalle Compras Agosto 2026'!$G:$G, 'Detalle Compras Agosto 2026'!$A:$A, B36, 'Detalle Compras Agosto 2026'!$B:$B, "Servicios") | N36: =COUNTIF('Detalle Compras Agosto 2026'!$A:$A, B36)
B37: 10 | C37: =SUMIFS('Detalle Compras Agosto 2026'!$G:$G, 'Detalle Compras Agosto 2026'!$A:$A, B37, 'Detalle Compras Agosto 2026'!$B:$B, "<>Servicios") | D37: =SUMIFS('Detalle Compras Agosto 2026'!$G:$G, 'Detalle Compras Agosto 2026'!$A:$A, B37, 'Detalle Compras Agosto 2026'!$B:$B, "Servicios") | E37: =C37+D37 | F37: =IF(E37>0, C37/E37, 0) | G37: =IF(E37>0, D37/E37, 0) | H37: =SUMIFS('Detalle Compras Agosto 2026'!$G:$G, 'Detalle Compras Agosto 2026'!$A:$A, B37, 'Detalle Compras Agosto 2026'!$B:$B, "Carnes") | I37: =SUMIFS('Detalle Compras Agosto 2026'!$G:$G, 'Detalle Compras Agosto 2026'!$A:$A, B37, 'Detalle Compras Agosto 2026'!$B:$B, "Verduras") | J37: =SUMIFS('Detalle Compras Agosto 2026'!$G:$G, 'Detalle Compras Agosto 2026'!$A:$A, B37, 'Detalle Compras Agosto 2026'!$B:$B, "Grano") | K37: =SUMIFS('Detalle Compras Agosto 2026'!$G:$G, 'Detalle Compras Agosto 2026'!$A:$A, B37, 'Detalle Compras Agosto 2026'!$B:$B, "Bebidas") | L37: =SUMIFS('Detalle Compras Agosto 2026'!$G:$G, 'Detalle Compras Agosto 2026'!$A:$A, B37, 'Detalle Compras Agosto 2026'!$B:$B, "Desechables") | M37: =SUMIFS('Detalle Compras Agosto 2026'!$G:$G, 'Detalle Compras Agosto 2026'!$A:$A, B37, 'Detalle Compras Agosto 2026'!$B:$B, "Servicios") | N37: =COUNTIF('Detalle Compras Agosto 2026'!$A:$A, B37)
B38: 11 | C38: =SUMIFS('Detalle Compras Agosto 2026'!$G:$G, 'Detalle Compras Agosto 2026'!$A:$A, B38, 'Detalle Compras Agosto 2026'!$B:$B, "<>Servicios") | D38: =SUMIFS('Detalle Compras Agosto 2026'!$G:$G, 'Detalle Compras Agosto 2026'!$A:$A, B38, 'Detalle Compras Agosto 2026'!$B:$B, "Servicios") | E38: =C38+D38 | F38: =IF(E38>0, C38/E38, 0) | G38: =IF(E38>0, D38/E38, 0) | H38: =SUMIFS('Detalle Compras Agosto 2026'!$G:$G, 'Detalle Compras Agosto 2026'!$A:$A, B38, 'Detalle Compras Agosto 2026'!$B:$B, "Carnes") | I38: =SUMIFS('Detalle Compras Agosto 2026'!$G:$G, 'Detalle Compras Agosto 2026'!$A:$A, B38, 'Detalle Compras Agosto 2026'!$B:$B, "Verduras") | J38: =SUMIFS('Detalle Compras Agosto 2026'!$G:$G, 'Detalle Compras Agosto 2026'!$A:$A, B38, 'Detalle Compras Agosto 2026'!$B:$B, "Grano") | K38: =SUMIFS('Detalle Compras Agosto 2026'!$G:$G, 'Detalle Compras Agosto 2026'!$A:$A, B38, 'Detalle Compras Agosto 2026'!$B:$B, "Bebidas") | L38: =SUMIFS('Detalle Compras Agosto 2026'!$G:$G, 'Detalle Compras Agosto 2026'!$A:$A, B38, 'Detalle Compras Agosto 2026'!$B:$B, "Desechables") | M38: =SUMIFS('Detalle Compras Agosto 2026'!$G:$G, 'Detalle Compras Agosto 2026'!$A:$A, B38, 'Detalle Compras Agosto 2026'!$B:$B, "Servicios") | N38: =COUNTIF('Detalle Compras Agosto 2026'!$A:$A, B38)
B39: 12 | C39: =SUMIFS('Detalle Compras Agosto 2026'!$G:$G, 'Detalle Compras Agosto 2026'!$A:$A, B39, 'Detalle Compras Agosto 2026'!$B:$B, "<>Servicios") | D39: =SUMIFS('Detalle Compras Agosto 2026'!$G:$G, 'Detalle Compras Agosto 2026'!$A:$A, B39, 'Detalle Compras Agosto 2026'!$B:$B, "Servicios") | E39: =C39+D39 | F39: =IF(E39>0, C39/E39, 0) | G39: =IF(E39>0, D39/E39, 0) | H39: =SUMIFS('Detalle Compras Agosto 2026'!$G:$G, 'Detalle Compras Agosto 2026'!$A:$A, B39, 'Detalle Compras Agosto 2026'!$B:$B, "Carnes") | I39: =SUMIFS('Detalle Compras Agosto 2026'!$G:$G, 'Detalle Compras Agosto 2026'!$A:$A, B39, 'Detalle Compras Agosto 2026'!$B:$B, "Verduras") | J39: =SUMIFS('Detalle Compras Agosto 2026'!$G:$G, 'Detalle Compras Agosto 2026'!$A:$A, B39, 'Detalle Compras Agosto 2026'!$B:$B, "Grano") | K39: =SUMIFS('Detalle Compras Agosto 2026'!$G:$G, 'Detalle Compras Agosto 2026'!$A:$A, B39, 'Detalle Compras Agosto 2026'!$B:$B, "Bebidas") | L39: =SUMIFS('Detalle Compras Agosto 2026'!$G:$G, 'Detalle Compras Agosto 2026'!$A:$A, B39, 'Detalle Compras Agosto 2026'!$B:$B, "Desechables") | M39: =SUMIFS('Detalle Compras Agosto 2026'!$G:$G, 'Detalle Compras Agosto 2026'!$A:$A, B39, 'Detalle Compras Agosto 2026'!$B:$B, "Servicios") | N39: =COUNTIF('Detalle Compras Agosto 2026'!$A:$A, B39)
... B58: 31 | C58: =SUMIFS('Detalle Compras Agosto 2026'!$G:$G, 'Detalle Compras Agosto 2026'!$A:$A, B58, 'Detalle Compras Agosto 2026'!$B:$B, "<>Servicios") | D58: =SUMIFS('Detalle Compras Agosto 2026'!$G:$G, 'Detalle Compras Agosto 2026'!$A:$A, B58, 'Detalle Compras Agosto 2026'!$B:$B, "Servicios") | E58: =C58+D58 | F58: =IF(E58>0, C58/E58, 0) | G58: =IF(E58>0, D58/E58, 0) | H58: =SUMIFS('Detalle Compras Agosto 2026'!$G:$G, 'Detalle Compras Agosto 2026'!$A:$A, B58, 'Detalle Compras Agosto 2026'!$B:$B, "Carnes") | I58: =SUMIFS('Detalle Compras Agosto 2026'!$G:$G, 'Detalle Compras Agosto 2026'!$A:$A, B58, 'Detalle Compras Agosto 2026'!$B:$B, "Verduras") | J58: =SUMIFS('Detalle Compras Agosto 2026'!$G:$G, 'Detalle Compras Agosto 2026'!$A:$A, B58, 'Detalle Compras Agosto 2026'!$B:$B, "Grano") | K58: =SUMIFS('Detalle Compras Agosto 2026'!$G:$G, 'Detalle Compras Agosto 2026'!$A:$A, B58, 'Detalle Compras Agosto 2026'!$B:$B, "Bebidas") | L58: =SUMIFS('Detalle Compras Agosto 2026'!$G:$G, 'Detalle Compras Agosto 2026'!$A:$A, B58, 'Detalle Compras Agosto 2026'!$B:$B, "Desechables") | M58: =SUMIFS('Detalle Compras Agosto 2026'!$G:$G, 'Detalle Compras Agosto 2026'!$A:$A, B58, 'Detalle Compras Agosto 2026'!$B:$B, "Servicios") | N58: =COUNTIF('Detalle Compras Agosto 2026'!$A:$A, B58)
B59: TOTAL MES | C59: =SUM(C28:C58) | D59: =SUM(D28:D58) | E59: =SUM(E28:E58) | F59: =C59/E59 | G59: =D59/E59 | H59: =SUM(H28:H58) | I59: =SUM(I28:I58) | J59: =SUM(J28:J58) | K59: =SUM(K28:K58) | L59: =SUM(L28:L58) | M59: =SUM(M28:M58) | N59: =SUM(N28:N58)
B60: PROMEDIO DIARIO | C60: =C59/COUNTIF($E$28:$E$58,">0") | D60: =D59/COUNTIF($E$28:$E$58,">0") | E60: =E59/COUNTIF($E$28:$E$58,">0") | F60: =C60/E60 | G60: =D60/E60 | H60: =H59/COUNTIF($E$28:$E$58,">0") | I60: =I59/COUNTIF($E$28:$E$58,">0") | J60: =J59/COUNTIF($E$28:$E$58,">0") | K60: =K59/COUNTIF($E$28:$E$58,">0") | L60: =L59/COUNTIF($E$28:$E$58,">0") | M60: =M59/COUNTIF($E$28:$E$58,">0") | N60: =N59/COUNTIF($E$28:$E$58,">0")
B61: MÁXIMO DIARIO (PICO) | C61: =MAX(C28:C58) | D61: =MAX(D28:D58) | E61: =MAX(E28:E58) | F61: - | G61: - | H61: =MAX(H28:H58) | I61: =MAX(I28:I58) | J61: =MAX(J28:J58) | K61: =MAX(K28:K58) | L61: =MAX(L28:L58) | M61: =MAX(M28:M58) | N61: =MAX(N28:N58)
B62: MÍNIMO DIARIO | C62: =MIN(C28:C58) | D62: =MIN(D28:D58) | E62: =MIN(E28:E58) | F62: - | G62: - | H62: =MIN(H28:H58) | I62: =MIN(I28:I58) | J62: =MIN(J28:J58) | K62: =MIN(K28:K58) | L62: =MIN(L28:L58) | M62: =MIN(M28:M58) | N62: =MIN(N28:N58)
B67: 4. TOP 10 INSUMOS DE MAYOR COSTO (MATERIA PRIMA) | I67: 5. TOP 10 GASTOS OPERACIONALES CLAVE (SERVICIOS Y NÓMINA)
B68: # | C68: Ítem / Insumo | D68: Categoría | E68: Compras | F68: Total Mes ($) | G68: % Costos | I68: # | J68: Concepto de Gasto | K68: Categoría | L68: Pagos | M68: Total Mes ($) | N68: % Gastos
...

Sheet Detalle Compras Agosto 2026
A1: Día | B1: Categoría (Pestaña) | C1: Ítem (Exacto en tu Excel) | D1: Descripción Original (PDF) | E1: Cantidad | F1: Costo Unitario | G1: Vr. Compra (Total)
A2: 1 | B2: Carnes | C2: Marisco | D2: Mix de Mariscos | E2: 5 | F2: 24000 | G2: 120000
A3: 1 | B3: Carnes | C3: Salmon | D3: Filete de Salmon Grande | E3: 4.5 | F3: 55000 | G3: 247500
A4: 1 | B4: Carnes | C4: Lomo de cerdo | D4: LOMO DE CERDO | E4: 12.7 | F4: 19500 | G4: 247650
A5: 1 | B5: Verduras | C5: Ajo pelado | D5: AJO PELADO X 1KG | E5: 10 | F5: 10900 | G5: 109000
A6: 1 | B6: Carnes | C6: Mix de verdura | D6: MIX DE VERDURAS PAQ X 1000G | E6: 10 | F6: 8487.4 | G6: 84874
A7: 1 | B7: Carnes | C7: Costilla san luis jr | D7: COSTILLA SAN LUIS JUNIOR T/M | E7: 38.53 | F7: 20900 | G7: 805277
A8: 1 | B8: Carnes | C8: Sobaco | D8: SOBACO | E8: 23.73 | F8: 25900 | G8: 614607
A9: 1 | B9: Carnes | C9: Sobrebarriga delgada | D9: SOBREBARRIGA DELGADA | E9: 20 | F9: 34500 | G9: 690000
A10: 1 | B10: Verduras | C10: Papa a la francesa paq 2.5 kl | D10: PAPA A LA FRANCESA FRITERS PAQ 2.5 KL | E10: 4 | F10: 15546.25 | G10: 62185
A11: 1 | B11: Carnes | C11: Tocineta barril | D11: TOCINETA BARRIL | E11: 126.75 | F11: 21900 | G11: 2775825
A12: 1 | B12: Carnes | C12: Punta de anca | D12: PUNTA DE ANCA PORC. PARRILLA | E12: 20.5 | F12: 44000 | G12: 902000
A13: 1 | B13: Grano | C13: Arroz | D13: ARROZ PROARROZ X 50 KL | E13: 2 | F13: 252000 | G13: 504000
... A219: 7 | B219: Carnes | C219: Sobaco | D219: SOBACO | E219: 24.71 | F219: 25900 | G219: 639989
A220: 7 | B220: Carnes | C220: Punta de anca | D220: PUNTA DE ANCA IMP PORC. PARRILLA | E220: 23 | F220: 44000 | G220: 1012000 | J220: 194887059
A221: 7 | B221: Carnes | C221: Lomo de caracho | D221: LOMO CARACHO PORCIONADO PARRILLA | E221: 21 | F221: 44000 | G221: 924000
A222: 7 | B222: Verduras | C222: Papa a la francesa paq 2.5 kl | D222: PAPA A LA FRANCESA FRITERS PAQ 2.5 KL | E222: 36 | F222: 15546.22 | G222: 559664 | J222: =SUM(G:G)
A223: 7 | B223: Carnes | C223: Muchacho res | D223: MUCHACHO DE RES | E223: 18.5 | F223: 29500 | G223: 545750
A224: 7 | B224: Carnes | C224: Tocineta barril | D224: TOCINETA BARRIL | E224: 64.65 | F224: 21900 | G224: 1415835 | J224: 5000000
A225: 7 | B225: Carnes | C225: Costilla de cerdo especial | D225: COSTILLA DE CERDO IBP 244M | E225: 13.3 | F225: 15400 | G225: 204820
A226: 7 | B226: Grano | C226: Leche de coco | D226: LECHE COCO | E226: 6 | F226: 21000 | G226: 126000
A227: 7 | B227: Desechables | C227: Esponja de brillo | D227: ESPIRAL ACERO LIMPIAYA | E227: 4 | F227: 2600 | G227: 10400
A228: 7 | B228: Verduras | C228: Yuca pelada | D228: 10 kl YUCA PELADA (Pasqualito) | E228: 10 | F228: 4500 | G228: 45000
A229: 13 | B229: Servicios | C229: Arreglo Tubos x Materiales | D229: 1 Pliego Lija | E229: 1 | F229: 5000 | G229: 5000
A230: 8 | B230: Grano | C230: Arroz | D230: ARROZ PROARROZ X 50 KL | E230: 2 | F230: 252000 | G230: 504000
A231: 8 | B231: Desechables | C231: Mercancias Varias Excentas | D231: MERCANCIAS VARIAS EXCENTAS | E231: 1 | F231: 76700 | G231: 76700
A232: 8 | B232: Grano | C232: Manteca | D232: MANTECA BLOQUE X 15KL | E232: 1 | F232: 130000 | G232: 130000
A233: 22 | B233: Bebidas | C233: Bloque media | D233: BLOQUE MEDIA (Hielo El Nevado SF44565) | E233: 2 | F233: 9500 | G233: 19000
A234: 23 | B234: Bebidas | C234: Bloque media | D234: BLOQUE MEDIA (Hielo El Nevado SF44594) | E234: 2 | F234: 9500 | G234: 19000
A235: 25 | B235: Bebidas | C235: Bloque media | D235: BLOQUE MEDIA (Hielo El Nevado SF44664) | E235: 2 | F235: 9500 | G235: 19000
A236: 8 | B236: Carnes | C236: Filete de pollo x 350 | D236: FILETE DE POLLO X 350G | E236: 15.6 | F236: 18500 | G236: 288600
... A695: 5 | B695: Servicios | C695: Pn sr | D695: 15 Pn sr | E695: 15 | F695: 12500 | G695: 187500
A696: 5 | B696: Servicios | C696: Prestamo Enith Mosquera | D696: Prestamo Enith Mosquera (Recibo Caja Menor) | E696: 1
A697: 24 | B697: Grano | C697: Arepas | D697: 150 arepas (Remision Arepas a Diario) | E697: 150 | F697: 150 | G697: 22500
A698: 1 | B698: Servicios | C698: Quincena Antonio Diaz | D698: Quincena del 16 al 31 de Julio /26 | E698: 1 | F698: 1250000 | G698: 1250000 | J698: =3523150+5241000
A699: 4 | B699: Bebidas | C699: H2o | D699: MANZANA H2OH 600 ML PET X 15 | E699: 7 | F699: 1820.73 | G699: 12745.11
A700: 24 | B700: Grano | C700: Comino molido | D700: Condimentos alinos guisason pimienta molida (Ahorra Mas Fac SIMP-000229545) | E700: 4 | F700: 2400 | G700: 9600
A701: 24 | B701: Grano | C701: Sal marina | D701: Sal Refisal marina x 400 gr (Ahorra Mas Fac SIMP-000229545) | E701: 2 | F701: 3500 | G701: 7000
A702: 24 | B702: Verduras | C702: Tomate chonto | D702: 6 Lb Tomate (Surplaza Remision 24/08) | E702: 6 | F702: 3450 | G702: 20700
A703: 20 | B703: Bebidas | C703: H2o | D703: MANZANA H2OH 600 ML PET X 15 | E703: 7 | F703: 1820.73 | G703: 12745.11
...

Sheet Inventario Cierre Agosto 2026
A2: RESTAURANTE CHOCLOS Y ASADOS LA FINCA SAS
A3: VALORIZACIÓN DE INVENTARIO FÍSICO DE CIERRE - AGOSTO 2026 (GRANOS, VERDURAS Y DESECHABLES)
A5: 1. TOTAL GRANOS | C5: 2. TOTAL VERDURAS | E5: 3. TOTAL DESECHABLES | G5: TOTAL INVENTARIO CIERRE
A6: =H26 | C6: =H45 | E6: =H100 | G6: =H102
A9: Grupo 1: Granos y Abarrotes
A10: # | B10: Descripción Original (Foto) | C10: Ítem Catálogo Oficial | D10: Categoría | E10: Cantidad | F10: Unidad / Medida | G10: Costo Unitario ($) | H10: Costo Total ($)
A11: 1 | B11: maggi | C11: Caldo maggi | D11: Grano | E11: 1 | F11: Paquete | G11: 12000 | H11: =E11*G11
A12: 2 | B12: comino | C12: Comino molido | D12: Grano | E12: 1 | F12: Lb | G12: 25000 | H12: =E12*G12
A13: 3 | B13: pasta sopa | C13: Pasta la muñeca | D13: Grano | E13: 2 | F13: Lb (500g) | G13: 3900 | H13: =E13*G13
A14: 4 | B14: Milo | C14: Milo | D14: Grano | E14: 1 | F14: Paquete (440g) | G14: 22000 | H14: =E14*G14
A15: 5 | B15: chocolate | C15: Chocolate | D15: Grano | E15: 0.5 | F15: Lb | G15: 37000 | H15: =E15*G15
A16: 6 | B16: arroz | C16: Arroz | D16: Grano | E16: 82 | F16: Kg | G16: 5040 | H16: =E16*G16
A17: 7 | B17: azucar | C17: Azucar | D17: Grano | E17: 12 | F17: Kg | G17: 4200 | H17: =E17*G17
A18: 8 | B18: zumo limon liquido | C18: Zumo de limon | D18: Grano | E18: 1 | F18: Tarro / Galón | G18: 45000 | H18: =E18*G18
A19: 9 | B19: frijol | C19: Frijol | D19: Grano | E19: 122.5 | F19: Kg | G19: 10500 | H19: =E19*G19
A20: 10 | B20: panela | C20: Panela | D20: Grano | E20: 144 | F20: Und | G20: 2166.67 | H20: =E20*G20
A21: 11 | B21: manteca | C21: Manteca | D21: Grano | E21: 51 | F21: Kg | G21: 8666.67 | H21: =E21*G21
A22: 12 | B22: Aceite | C22: Bidon de aceite | D22: Grano | E22: 1 | F22: Bidón (20L) | G22: 116000 | H22: =E22*G22
... A25: 15 | B25: leche | C25: Leche entera | D25: Grano | E25: 21 | F25: Bolsas (1L) | G25: 3800 | H25: =E25*G25
A26: SUBTOTAL GRUPO 1: GRANOS Y ABARROTES | H26: =SUM(H11:H25)
A28: Grupo 2: Verduras
A29: # | B29: Descripción Original (Foto) | C29: Ítem Catálogo Oficial | D29: Categoría | E29: Cantidad | F29: Unidad / Medida | G29: Costo Unitario ($) | H29: Costo Total ($)
A30: 1 | B30: batavia | C30: Lechuga batavia | D30: Verduras | E30: 16 | F30: Kg | G30: 2800 | H30: =E30*G30
A31: 2 | B31: limon | C31: Limon tahiti | D31: Verduras | E31: 9 | F31: Kg | G31: 3200 | H31: =E31*G31
A32: 3 | B32: c. larga | C32: Cebolla larga | D32: Verduras | E32: 6.3 | F32: Kg | G32: 3500 | H32: =E32*G32
A33: 4 | B33: milano | C33: Tomate milano | D33: Verduras | E33: 0.4 | F33: Kg (o 4kg) | G33: 4500 | H33: =E33*G33
A34: 5 | B34: pepino | C34: Pepino comun | D34: Verduras | E34: 0.4 | F34: Kg | G34: 3000 | H34: =E34*G34
A35: 6 | B35: zanahoria | C35: Zanahoria | D35: Verduras | E35: 0.5 | F35: Kg | G35: 2500 | H35: =E35*G35
A36: 7 | B36: cabezona | C36: Cebolla cabezona | D36: Verduras | E36: 3.7 | F36: Kg | G36: 3800 | H36: =E36*G36
A37: 8 | B37: yuca | C37: Yuca pelada | D37: Verduras | E37: 10 | F37: Kg | G37: 4500 | H37: =E37*G37
A38: 9 | B38: mazorca | C38: Mazorca | D38: Verduras | E38: 4.5 | F38: Kg | G38: 3600 | H38: =E38*G38
A39: 10 | B39: arracacha | C39: Arracacha | D39: Verduras | E39: 2.5 | F39: Kg | G39: 6500 | H39: =E39*G39
A40: 11 | B40: cimarron | C40: Cimarron | D40: Verduras | E40: 3 | F40: Atados | G40: 2500 | H40: =E40*G40
A41: 12 | B41: apio | C41: Apio | D41: Verduras | E41: 1.2 | F41: Kg | G41: 2500 | H41: =E41*G41
... A44: 15 | B44: platano | C44: Platano maduro / verde | D44: Verduras | E44: 21 | F44: Kg (10+11) | G44: 2200 | H44: =E44*G44
A45: SUBTOTAL GRUPO 2: VERDURAS Y FRUVER | H45: =SUM(H30:H44)
A47: Grupo 3: Desechables y Productos de Aseo
A48: # | B48: Descripción Original (Foto) | C48: Ítem Catálogo Oficial | D48: Categoría | E48: Cantidad | F48: Unidad / Medida | G48: Costo Unitario ($) | H48: Costo Total ($)
A49: 1 | B49: P3 negro | C49: Base p3 negro | D49: Desechables | E49: 15 | F49: Und | G49: 480 | H49: =E49*G49
A50: 2 | B50: Acento | C50: Acento x 500 | D50: Desechables | E50: 2 | F50: Lb | G50: 6200 | H50: =E50*G50
...
